Workbook

Sheet Today
B2: MOMENTUM · TODAY
B3: =UPPER(TEXT(TODAY(),"dddd")) | E3: =TEXT(TODAY(),"d mmmm yyyy")
B4: =IF(SUMPRODUCT(--(Engine!$Z$2:$Z$11<>""))=0,"Nothing is being tracked yet — open Start Here and name your habits.","You are in week "&TEXT(MIN(52,MAX(1,INT((TODAY()-'Start Here'!$E$6)/7)+1)),"00")&" of 52.")
B6: =IF(SUMPRODUCT(--(Engine!$Z$2:$Z$11<>""))=0,"",IF(SUMPRODUCT(--(Engine!$AA$2:$AA$11>0),--(Engine!$AD$2:$AD$11=0))=0,"Every live streak is already logged today. Nothing to lose tonight.",SUMPRODUCT(--(Engine!$AA$2:$AA$11>0),--(Engine!$AD$2:$AD$11=0))&IF(SUMPRODUCT(--(Engine!$AA$2:$AA$11>0),--(Engine!$AD$2:$AD$11=0))=1," streak ends tonight unless you log it — "," streaks end tonight unless you log them — ")&TEXT(TODAY(),"d mmm")&"."))
B7: =IF(SUMPRODUCT(--(Engine!$Z$2:$Z$11<>""))=0,"",TEXT(SUMPRODUCT(--(Engine!$Z$2:$Z$11<>""),--(Engine!$AD$2:$AD$11=1)),"0")&" of "&TEXT(SUMPRODUCT(--(Engine!$Z$2:$Z$11<>"")),"0")&" habits logged today.")
B11: HABIT | C11: TODAY | D11: STREAK | E11: STATUS | F11: NEXT BADGE
B12: =IF('Start Here'!C11="","",'Start Here'!C11) | C12: =IF($B12="","",IF(Engine!$AD$2=1,"✓","—")) | D12: =IF($B12="","",Engine!$AA$2) | E12: =IF($B12="","",IF(Engine!$AD$2=1,"logged",IF(Engine!$AA$2>0,"AT RISK","not yet"))) | F12: =IF($B12="","",IF(Engine!$AE$2="","every badge earned",TEXT(Engine!$AE$2,"0")&"-day badge in "&TEXT(Engine!$AF$2,"0")&" days"))
B13: =IF('Start Here'!C12="","",'Start Here'!C12) | C13: =IF($B13="","",IF(Engine!$AD$3=1,"✓","—")) | D13: =IF($B13="","",Engine!$AA$3) | E13: =IF($B13="","",IF(Engine!$AD$3=1,"logged",IF(Engine!$AA$3>0,"AT RISK","not yet"))) | F13: =IF($B13="","",IF(Engine!$AE$3="","every badge earned",TEXT(Engine!$AE$3,"0")&"-day badge in "&TEXT(Engine!$AF$3,"0")&" days"))
B14: =IF('Start Here'!C13="","",'Start Here'!C13) | C14: =IF($B14="","",IF(Engine!$AD$4=1,"✓","—")) | D14: =IF($B14="","",Engine!$AA$4) | E14: =IF($B14="","",IF(Engine!$AD$4=1,"logged",IF(Engine!$AA$4>0,"AT RISK","not yet"))) | F14: =IF($B14="","",IF(Engine!$AE$4="","every badge earned",TEXT(Engine!$AE$4,"0")&"-day badge in "&TEXT(Engine!$AF$4,"0")&" days"))
B15: =IF('Start Here'!C14="","",'Start Here'!C14) | C15: =IF($B15="","",IF(Engine!$AD$5=1,"✓","—")) | D15: =IF($B15="","",Engine!$AA$5) | E15: =IF($B15="","",IF(Engine!$AD$5=1,"logged",IF(Engine!$AA$5>0,"AT RISK","not yet"))) | F15: =IF($B15="","",IF(Engine!$AE$5="","every badge earned",TEXT(Engine!$AE$5,"0")&"-day badge in "&TEXT(Engine!$AF$5,"0")&" days"))
B16: =IF('Start Here'!C15="","",'Start Here'!C15) | C16: =IF($B16="","",IF(Engine!$AD$6=1,"✓","—")) | D16: =IF($B16="","",Engine!$AA$6) | E16: =IF($B16="","",IF(Engine!$AD$6=1,"logged",IF(Engine!$AA$6>0,"AT RISK","not yet"))) | F16: =IF($B16="","",IF(Engine!$AE$6="","every badge earned",TEXT(Engine!$AE$6,"0")&"-day badge in "&TEXT(Engine!$AF$6,"0")&" days"))
B17: =IF('Start Here'!C16="","",'Start Here'!C16) | C17: =IF($B17="","",IF(Engine!$AD$7=1,"✓","—")) | D17: =IF($B17="","",Engine!$AA$7) | E17: =IF($B17="","",IF(Engine!$AD$7=1,"logged",IF(Engine!$AA$7>0,"AT RISK","not yet"))) | F17: =IF($B17="","",IF(Engine!$AE$7="","every badge earned",TEXT(Engine!$AE$7,"0")&"-day badge in "&TEXT(Engine!$AF$7,"0")&" days"))
B18: =IF('Start Here'!C17="","",'Start Here'!C17) | C18: =IF($B18="","",IF(Engine!$AD$8=1,"✓","—")) | D18: =IF($B18="","",Engine!$AA$8) | E18: =IF($B18="","",IF(Engine!$AD$8=1,"logged",IF(Engine!$AA$8>0,"AT RISK","not yet"))) | F18: =IF($B18="","",IF(Engine!$AE$8="","every badge earned",TEXT(Engine!$AE$8,"0")&"-day badge in "&TEXT(Engine!$AF$8,"0")&" days"))
B19: =IF('Start Here'!C18="","",'Start Here'!C18) | C19: =IF($B19="","",IF(Engine!$AD$9=1,"✓","—")) | D19: =IF($B19="","",Engine!$AA$9) | E19: =IF($B19="","",IF(Engine!$AD$9=1,"logged",IF(Engine!$AA$9>0,"AT RISK","not yet"))) | F19: =IF($B19="","",IF(Engine!$AE$9="","every badge earned",TEXT(Engine!$AE$9,"0")&"-day badge in "&TEXT(Engine!$AF$9,"0")&" days"))
B20: =IF('Start Here'!C19="","",'Start Here'!C19) | C20: =IF($B20="","",IF(Engine!$AD$10=1,"✓","—")) | D20: =IF($B20="","",Engine!$AA$10) | E20: =IF($B20="","",IF(Engine!$AD$10=1,"logged",IF(Engine!$AA$10>0,"AT RISK","not yet"))) | F20: =IF($B20="","",IF(Engine!$AE$10="","every badge earned",TEXT(Engine!$AE$10,"0")&"-day badge in "&TEXT(Engine!$AF$10,"0")&" days"))
B21: =IF('Start Here'!C20="","",'Start Here'!C20) | C21: =IF($B21="","",IF(Engine!$AD$11=1,"✓","—")) | D21: =IF($B21="","",Engine!$AA$11) | E21: =IF($B21="","",IF(Engine!$AD$11=1,"logged",IF(Engine!$AA$11>0,"AT RISK","not yet"))) | F21: =IF($B21="","",IF(Engine!$AE$11="","every badge earned",TEXT(Engine!$AE$11,"0")&"-day badge in "&TEXT(Engine!$AF$11,"0")&" days"))
B23: Ticking happens in the week tabs: | C23: ◆ DASHBOARD | E23: ◆ START HERE
B25: The Dashboard highlights the week you are in — two taps to today.

Sheet Start Here
B2: MOMENTUM
B3: WEEKLY HABIT SYSTEM · 52 WEEKS · 10 HABITS
B5: 1 · SET YOUR START DATE | J5: HOW IT WORKS
C6: Pick the Monday you want Week 01 to begin | E6: =DATE(2026,1,5) | G6: ◀ type here | J6: Every week has its own tab: W01 → W52.
B8: 2 · NAME YOUR HABITS | J8: In a week tab, click a day cell and choose:
C9: Anything you leave blank simply disappears from the tracker. | J9: ✓ did it
C10: HABIT | E10: GOAL / WEEK | G10: CURRENT STREAK | J10: ✗ missed it on purpose
B11: 1 | C11: Move my body 30 min | E11: 5 | G11: =IF($C11="","",Engine!$AA$2) | J11: Leaving it blank also counts as a miss.
B12: 2 | C12: Read 10 pages | E12: 6 | G12: =IF($C12="","",Engine!$AA$3)
B13: 3 | C13: Lights out by 23:00 | E13: 5 | G13: =IF($C13="","",Engine!$AA$4) | J13: STREAK counts consecutive ✓ days and rolls
B14: 4 | C14: Drink 2L water | E14: 7 | G14: =IF($C14="","",Engine!$AA$5) | J14: straight across week tabs — miss one day and
B15: 5 | C15: Plan tomorrow tonight | E15: 5 | G15: =IF($C15="","",Engine!$AA$6) | J15: it resets to zero. That is the whole game.
B16: 6 | G16: =IF($C16="","",Engine!$AA$7)
B17: 7 | G17: =IF($C17="","",Engine!$AA$8) | J17: Badges unlock automatically at 7, 30, 100 and
B18: 8 | G18: =IF($C18="","",Engine!$AA$9) | J18: 365 days. They are based on your best streak,
B19: 9 | G19: =IF($C19="","",Engine!$AA$10) | J19: so a badge once earned is yours for good.
B20: 10 | G20: =IF($C20="","",Engine!$AA$11)
J21: Nothing here needs the internet, an account or
B22: 3 · START TRACKING | J22: a subscription. The file is yours.
C23: Open your week, pick ✓ from the dropdown, done. Takes 20 seconds.
C24: ◆ OPEN DASHBOARD | E24: ▶ GO TO WEEK 01
J26: TIP
J27: Track 3 habits, not 10. Streaks die of ambition.

Sheet Dashboard
C2: MOMENTUM · WEEKLY HABIT SYSTEM
C3: DASHBOARD | P3: ◆ START HERE
C4: Everything on this page fills itself in. You only ever tick boxes in the week tabs. | P4: ▶ WEEK 01
C6: TOTAL CHECK-INS | G6: BEST STREAK | K6: STREAKS ALIVE | O6: YEAR PROGRESS
C7: =SUM(Engine!$AC$2:$AC$11) | G7: =MAX(Engine!$AB$2:$AB$11) | K7: =SUMPRODUCT(--(Engine!$AA$2:$AA$11>0)) | O7: =IFERROR(MAX(0,MIN(1,(TODAY()-'Start Here'!$E$6+1)/364)),"")
C8: days ticked since day one | G8: your longest unbroken run | K8: habits still running today | O8: of your 52 weeks
C11: YOUR HABITS | O11: MILESTONES (best streak)
C12: HABIT | I12: DONE | K12: CURRENT | M12: BEST | O12: 7 | P12: 30 | Q12: 100 | R12: 365
C13: =IF('Start Here'!C11="","",'Start Here'!C11) | I13: =IF($C13="","",Engine!$AC$2) | K13: =IF($C13="","",Engine!$AA$2) | M13: =IF($C13="","",Engine!$AB$2) | O13: =IF($C13="","",IF(Engine!$AB$2>=7,"✔","·")) | P13: =IF($C13="","",IF(Engine!$AB$2>=30,"✔","·")) | Q13: =IF($C13="","",IF(Engine!$AB$2>=100,"✔","·")) | R13: =IF($C13="","",IF(Engine!$AB$2>=365,"✔","·"))
C14: =IF('Start Here'!C12="","",'Start Here'!C12) | I14: =IF($C14="","",Engine!$AC$3) | K14: =IF($C14="","",Engine!$AA$3) | M14: =IF($C14="","",Engine!$AB$3) | O14: =IF($C14="","",IF(Engine!$AB$3>=7,"✔","·")) | P14: =IF($C14="","",IF(Engine!$AB$3>=30,"✔","·")) | Q14: =IF($C14="","",IF(Engine!$AB$3>=100,"✔","·")) | R14: =IF($C14="","",IF(Engine!$AB$3>=365,"✔","·"))
C15: =IF('Start Here'!C13="","",'Start Here'!C13) | I15: =IF($C15="","",Engine!$AC$4) | K15: =IF($C15="","",Engine!$AA$4) | M15: =IF($C15="","",Engine!$AB$4) | O15: =IF($C15="","",IF(Engine!$AB$4>=7,"✔","·")) | P15: =IF($C15="","",IF(Engine!$AB$4>=30,"✔","·")) | Q15: =IF($C15="","",IF(Engine!$AB$4>=100,"✔","·")) | R15: =IF($C15="","",IF(Engine!$AB$4>=365,"✔","·"))
C16: =IF('Start Here'!C14="","",'Start Here'!C14) | I16: =IF($C16="","",Engine!$AC$5) | K16: =IF($C16="","",Engine!$AA$5) | M16: =IF($C16="","",Engine!$AB$5) | O16: =IF($C16="","",IF(Engine!$AB$5>=7,"✔","·")) | P16: =IF($C16="","",IF(Engine!$AB$5>=30,"✔","·")) | Q16: =IF($C16="","",IF(Engine!$AB$5>=100,"✔","·")) | R16: =IF($C16="","",IF(Engine!$AB$5>=365,"✔","·"))
C17: =IF('Start Here'!C15="","",'Start Here'!C15) | I17: =IF($C17="","",Engine!$AC$6) | K17: =IF($C17="","",Engine!$AA$6) | M17: =IF($C17="","",Engine!$AB$6) | O17: =IF($C17="","",IF(Engine!$AB$6>=7,"✔","·")) | P17: =IF($C17="","",IF(Engine!$AB$6>=30,"✔","·")) | Q17: =IF($C17="","",IF(Engine!$AB$6>=100,"✔","·")) | R17: =IF($C17="","",IF(Engine!$AB$6>=365,"✔","·"))
C18: =IF('Start Here'!C16="","",'Start Here'!C16) | I18: =IF($C18="","",Engine!$AC$7) | K18: =IF($C18="","",Engine!$AA$7) | M18: =IF($C18="","",Engine!$AB$7) | O18: =IF($C18="","",IF(Engine!$AB$7>=7,"✔","·")) | P18: =IF($C18="","",IF(Engine!$AB$7>=30,"✔","·")) | Q18: =IF($C18="","",IF(Engine!$AB$7>=100,"✔","·")) | R18: =IF($C18="","",IF(Engine!$AB$7>=365,"✔","·"))
C19: =IF('Start Here'!C17="","",'Start Here'!C17) | I19: =IF($C19="","",Engine!$AC$8) | K19: =IF($C19="","",Engine!$AA$8) | M19: =IF($C19="","",Engine!$AB$8) | O19: =IF($C19="","",IF(Engine!$AB$8>=7,"✔","·")) | P19: =IF($C19="","",IF(Engine!$AB$8>=30,"✔","·")) | Q19: =IF($C19="","",IF(Engine!$AB$8>=100,"✔","·")) | R19: =IF($C19="","",IF(Engine!$AB$8>=365,"✔","·"))
C20: =IF('Start Here'!C18="","",'Start Here'!C18) | I20: =IF($C20="","",Engine!$AC$9) | K20: =IF($C20="","",Engine!$AA$9) | M20: =IF($C20="","",Engine!$AB$9) | O20: =IF($C20="","",IF(Engine!$AB$9>=7,"✔","·")) | P20: =IF($C20="","",IF(Engine!$AB$9>=30,"✔","·")) | Q20: =IF($C20="","",IF(Engine!$AB$9>=100,"✔","·")) | R20: =IF($C20="","",IF(Engine!$AB$9>=365,"✔","·"))
C21: =IF('Start Here'!C19="","",'Start Here'!C19) | I21: =IF($C21="","",Engine!$AC$10) | K21: =IF($C21="","",Engine!$AA$10) | M21: =IF($C21="","",Engine!$AB$10) | O21: =IF($C21="","",IF(Engine!$AB$10>=7,"✔","·")) | P21: =IF($C21="","",IF(Engine!$AB$10>=30,"✔","·")) | Q21: =IF($C21="","",IF(Engine!$AB$10>=100,"✔","·")) | R21: =IF($C21="","",IF(Engine!$AB$10>=365,"✔","·"))
C22: =IF('Start Here'!C20="","",'Start Here'!C20) | I22: =IF($C22="","",Engine!$AC$11) | K22: =IF($C22="","",Engine!$AA$11) | M22: =IF($C22="","",Engine!$AB$11) | O22: =IF($C22="","",IF(Engine!$AB$11>=7,"✔","·")) | P22: =IF($C22="","",IF(Engine!$AB$11>=30,"✔","·")) | Q22: =IF($C22="","",IF(Engine!$AB$11>=100,"✔","·")) | R22: =IF($C22="","",IF(Engine!$AB$11>=365,"✔","·"))
C25: THE YEAR AT A GLANCE
C26: Click a week to jump straight to it. The week you are in is highlighted; the number underneath is that week's score against your goals.
C29: 01 | D29: 02 | E29: 03 | F29: 04 | G29: 05 | H29: 06 | I29: 07 | J29: 08 | K29: 09 | L29: 10 | M29: 11 | N29: 12 | O29: 13
C30: =IF(OR(W01!$C$7>TODAY(),SUM('Start Here'!$E$11:$E$20)=0),"",MIN(1,(COUNTA(W01!$C$9:$I$18)-COUNTIF(W01!$C$9:$I$18,"✗"))/SUM('Start Here'!$E$11:$E$20))) | D30: =IF(OR(W02!$C$7>TODAY(),SUM('Start Here'!$E$11:$E$20)=0),"",MIN(1,(COUNTA(W02!$C$9:$I$18)-COUNTIF(W02!$C$9:$I$18,"✗"))/SUM('Start Here'!$E$11:$E$20))) | E30: =IF(OR(W03!$C$7>TODAY(),SUM('Start Here'!$E$11:$E$20)=0),"",MIN(1,(COUNTA(W03!$C$9:$I$18)-COUNTIF(W03!$C$9:$I$18,"✗"))/SUM('Start Here'!$E$11:$E$20))) | F30: =IF(OR(W04!$C$7>TODAY(),SUM('Start Here'!$E$11:$E$20)=0),"",MIN(1,(COUNTA(W04!$C$9:$I$18)-COUNTIF(W04!$C$9:$I$18,"✗"))/SUM('Start Here'!$E$11:$E$20))) | G30: =IF(OR(W05!$C$7>TODAY(),SUM('Start Here'!$E$11:$E$20)=0),"",MIN(1,(COUNTA(W05!$C$9:$I$18)-COUNTIF(W05!$C$9:$I$18,"✗"))/SUM('Start Here'!$E$11:$E$20))) | H30: =IF(OR(W06!$C$7>TODAY(),SUM('Start Here'!$E$11:$E$20)=0),"",MIN(1,(COUNTA(W06!$C$9:$I$18)-COUNTIF(W06!$C$9:$I$18,"✗"))/SUM('Start Here'!$E$11:$E$20))) | I30: =IF(OR(W07!$C$7>TODAY(),SUM('Start Here'!$E$11:$E$20)=0),"",MIN(1,(COUNTA(W07!$C$9:$I$18)-COUNTIF(W07!$C$9:$I$18,"✗"))/SUM('Start Here'!$E$11:$E$20))) | J30: =IF(OR(W08!$C$7>TODAY(),SUM('Start Here'!$E$11:$E$20)=0),"",MIN(1,(COUNTA(W08!$C$9:$I$18)-COUNTIF(W08!$C$9:$I$18,"✗"))/SUM('Start Here'!$E$11:$E$20))) | K30: =IF(OR(W09!$C$7>TODAY(),SUM('Start Here'!$E$11:$E$20)=0),"",MIN(1,(COUNTA(W09!$C$9:$I$18)-COUNTIF(W09!$C$9:$I$18,"✗"))/SUM('Start Here'!$E$11:$E$20))) | L30: =IF(OR(W10!$C$7>TODAY(),SUM('Start Here'!$E$11:$E$20)=0),"",MIN(1,(COUNTA(W10!$C$9:$I$18)-COUNTIF(W10!$C$9:$I$18,"✗"))/SUM('Start Here'!$E$11:$E$20))) | M30: =IF(OR(W11!$C$7>TODAY(),SUM('Start Here'!$E$11:$E$20)=0),"",MIN(1,(COUNTA(W11!$C$9:$I$18)-COUNTIF(W11!$C$9:$I$18,"✗"))/SUM('Start Here'!$E$11:$E$20))) | N30: =IF(OR(W12!$C$7>TODAY(),SUM('Start Here'!$E$11:$E$20)=0),"",MIN(1,(COUNTA(W12!$C$9:$I$18)-COUNTIF(W12!$C$9:$I$18,"✗"))/SUM('Start Here'!$E$11:$E$20))) | O30: =IF(OR(W13!$C$7>TODAY(),SUM('Start Here'!$E$11:$E$20)=0),"",MIN(1,(COUNTA(W13!$C$9:$I$18)-COUNTIF(W13!$C$9:$I$18,"✗"))/SUM('Start Here'!$E$11:$E$20)))
C31: =W01!$C$7 | D31: =W02!$C$7 | E31: =W03!$C$7 | F31: =W04!$C$7 | G31: =W05!$C$7 | H31: =W06!$C$7 | I31: =W07!$C$7 | J31: =W08!$C$7 | K31: =W09!$C$7 | L31: =W10!$C$7 | M31: =W11!$C$7 | N31: =W12!$C$7 | O31: =W13!$C$7
C33: 14 | D33: 15 | E33: 16 | F33: 17 | G33: 18 | H33: 19 | I33: 20 | J33: 21 | K33: 22 | L33: 23 | M33: 24 | N33: 25 | O33: 26
C34: =IF(OR(W14!$C$7>TODAY(),SUM('Start Here'!$E$11:$E$20)=0),"",MIN(1,(COUNTA(W14!$C$9:$I$18)-COUNTIF(W14!$C$9:$I$18,"✗"))/SUM('Start Here'!$E$11:$E$20))) | D34: =IF(OR(W15!$C$7>TODAY(),SUM('Start Here'!$E$11:$E$20)=0),"",MIN(1,(COUNTA(W15!$C$9:$I$18)-COUNTIF(W15!$C$9:$I$18,"✗"))/SUM('Start Here'!$E$11:$E$20))) | E34: =IF(OR(W16!$C$7>TODAY(),SUM('Start Here'!$E$11:$E$20)=0),"",MIN(1,(COUNTA(W16!$C$9:$I$18)-COUNTIF(W16!$C$9:$I$18,"✗"))/SUM('Start Here'!$E$11:$E$20))) | F34: =IF(OR(W17!$C$7>TODAY(),SUM('Start Here'!$E$11:$E$20)=0),"",MIN(1,(COUNTA(W17!$C$9:$I$18)-COUNTIF(W17!$C$9:$I$18,"✗"))/SUM('Start Here'!$E$11:$E$20))) | G34: =IF(OR(W18!$C$7>TODAY(),SUM('Start Here'!$E$11:$E$20)=0),"",MIN(1,(COUNTA(W18!$C$9:$I$18)-COUNTIF(W18!$C$9:$I$18,"✗"))/SUM('Start Here'!$E$11:$E$20))) | H34: =IF(OR(W19!$C$7>TODAY(),SUM('Start Here'!$E$11:$E$20)=0),"",MIN(1,(COUNTA(W19!$C$9:$I$18)-COUNTIF(W19!$C$9:$I$18,"✗"))/SUM('Start Here'!$E$11:$E$20))) | I34: =IF(OR(W20!$C$7>TODAY(),SUM('Start Here'!$E$11:$E$20)=0),"",MIN(1,(COUNTA(W20!$C$9:$I$18)-COUNTIF(W20!$C$9:$I$18,"✗"))/SUM('Start Here'!$E$11:$E$20))) | J34: =IF(OR(W21!$C$7>TODAY(),SUM('Start Here'!$E$11:$E$20)=0),"",MIN(1,(COUNTA(W21!$C$9:$I$18)-COUNTIF(W21!$C$9:$I$18,"✗"))/SUM('Start Here'!$E$11:$E$20))) | K34: =IF(OR(W22!$C$7>TODAY(),SUM('Start Here'!$E$11:$E$20)=0),"",MIN(1,(COUNTA(W22!$C$9:$I$18)-COUNTIF(W22!$C$9:$I$18,"✗"))/SUM('Start Here'!$E$11:$E$20))) | L34: =IF(OR(W23!$C$7>TODAY(),SUM('Start Here'!$E$11:$E$20)=0),"",MIN(1,(COUNTA(W23!$C$9:$I$18)-COUNTIF(W23!$C$9:$I$18,"✗"))/SUM('Start Here'!$E$11:$E$20))) | M34: =IF(OR(W24!$C$7>TODAY(),SUM('Start Here'!$E$11:$E$20)=0),"",MIN(1,(COUNTA(W24!$C$9:$I$18)-COUNTIF(W24!$C$9:$I$18,"✗"))/SUM('Start Here'!$E$11:$E$20))) | N34: =IF(OR(W25!$C$7>TODAY(),SUM('Start Here'!$E$11:$E$20)=0),"",MIN(1,(COUNTA(W25!$C$9:$I$18)-COUNTIF(W25!$C$9:$I$18,"✗"))/SUM('Start Here'!$E$11:$E$20))) | O34: =IF(OR(W26!$C$7>TODAY(),SUM('Start Here'!$E$11:$E$20)=0),"",MIN(1,(COUNTA(W26!$C$9:$I$18)-COUNTIF(W26!$C$9:$I$18,"✗"))/SUM('Start Here'!$E$11:$E$20)))
C35: =W14!$C$7 | D35: =W15!$C$7 | E35: =W16!$C$7 | F35: =W17!$C$7 | G35: =W18!$C$7 | H35: =W19!$C$7 | I35: =W20!$C$7 | J35: =W21!$C$7 | K35: =W22!$C$7 | L35: =W23!$C$7 | M35: =W24!$C$7 | N35: =W25!$C$7 | O35: =W26!$C$7
C37: 27 | D37: 28 | E37: 29 | F37: 30 | G37: 31 | H37: 32 | I37: 33 | J37: 34 | K37: 35 | L37: 36 | M37: 37 | N37: 38 | O37: 39
C38: =IF(OR(W27!$C$7>TODAY(),SUM('Start Here'!$E$11:$E$20)=0),"",MIN(1,(COUNTA(W27!$C$9:$I$18)-COUNTIF(W27!$C$9:$I$18,"✗"))/SUM('Start Here'!$E$11:$E$20))) | D38: =IF(OR(W28!$C$7>TODAY(),SUM('Start Here'!$E$11:$E$20)=0),"",MIN(1,(COUNTA(W28!$C$9:$I$18)-COUNTIF(W28!$C$9:$I$18,"✗"))/SUM('Start Here'!$E$11:$E$20))) | E38: =IF(OR(W29!$C$7>TODAY(),SUM('Start Here'!$E$11:$E$20)=0),"",MIN(1,(COUNTA(W29!$C$9:$I$18)-COUNTIF(W29!$C$9:$I$18,"✗"))/SUM('Start Here'!$E$11:$E$20))) | F38: =IF(OR(W30!$C$7>TODAY(),SUM('Start Here'!$E$11:$E$20)=0),"",MIN(1,(COUNTA(W30!$C$9:$I$18)-COUNTIF(W30!$C$9:$I$18,"✗"))/SUM('Start Here'!$E$11:$E$20))) | G38: =IF(OR(W31!$C$7>TODAY(),SUM('Start Here'!$E$11:$E$20)=0),"",MIN(1,(COUNTA(W31!$C$9:$I$18)-COUNTIF(W31!$C$9:$I$18,"✗"))/SUM('Start Here'!$E$11:$E$20))) | H38: =IF(OR(W32!$C$7>TODAY(),SUM('Start Here'!$E$11:$E$20)=0),"",MIN(1,(COUNTA(W32!$C$9:$I$18)-COUNTIF(W32!$C$9:$I$18,"✗"))/SUM('Start Here'!$E$11:$E$20))) | I38: =IF(OR(W33!$C$7>TODAY(),SUM('Start Here'!$E$11:$E$20)=0),"",MIN(1,(COUNTA(W33!$C$9:$I$18)-COUNTIF(W33!$C$9:$I$18,"✗"))/SUM('Start Here'!$E$11:$E$20))) | J38: =IF(OR(W34!$C$7>TODAY(),SUM('Start Here'!$E$11:$E$20)=0),"",MIN(1,(COUNTA(W34!$C$9:$I$18)-COUNTIF(W34!$C$9:$I$18,"✗"))/SUM('Start Here'!$E$11:$E$20))) | K38: =IF(OR(W35!$C$7>TODAY(),SUM('Start Here'!$E$11:$E$20)=0),"",MIN(1,(COUNTA(W35!$C$9:$I$18)-COUNTIF(W35!$C$9:$I$18,"✗"))/SUM('Start Here'!$E$11:$E$20))) | L38: =IF(OR(W36!$C$7>TODAY(),SUM('Start Here'!$E$11:$E$20)=0),"",MIN(1,(COUNTA(W36!$C$9:$I$18)-COUNTIF(W36!$C$9:$I$18,"✗"))/SUM('Start Here'!$E$11:$E$20))) | M38: =IF(OR(W37!$C$7>TODAY(),SUM('Start Here'!$E$11:$E$20)=0),"",MIN(1,(COUNTA(W37!$C$9:$I$18)-COUNTIF(W37!$C$9:$I$18,"✗"))/SUM('Start Here'!$E$11:$E$20))) | N38: =IF(OR(W38!$C$7>TODAY(),SUM('Start Here'!$E$11:$E$20)=0),"",MIN(1,(COUNTA(W38!$C$9:$I$18)-COUNTIF(W38!$C$9:$I$18,"✗"))/SUM('Start Here'!$E$11:$E$20))) | O38: =IF(OR(W39!$C$7>TODAY(),SUM('Start Here'!$E$11:$E$20)=0),"",MIN(1,(COUNTA(W39!$C$9:$I$18)-COUNTIF(W39!$C$9:$I$18,"✗"))/SUM('Start Here'!$E$11:$E$20)))
C39: =W27!$C$7 | D39: =W28!$C$7 | E39: =W29!$C$7 | F39: =W30!$C$7 | G39: =W31!$C$7 | H39: =W32!$C$7 | I39: =W33!$C$7 | J39: =W34!$C$7 | K39: =W35!$C$7 | L39: =W36!$C$7 | M39: =W37!$C$7 | N39: =W38!$C$7 | O39: =W39!$C$7
C41: 40 | D41: 41 | E41: 42 | F41: 43 | G41: 44 | H41: 45 | I41: 46 | J41: 47 | K41: 48 | L41: 49 | M41: 50 | N41: 51 | O41: 52
C42: =IF(OR(W40!$C$7>TODAY(),SUM('Start Here'!$E$11:$E$20)=0),"",MIN(1,(COUNTA(W40!$C$9:$I$18)-COUNTIF(W40!$C$9:$I$18,"✗"))/SUM('Start Here'!$E$11:$E$20))) | D42: =IF(OR(W41!$C$7>TODAY(),SUM('Start Here'!$E$11:$E$20)=0),"",MIN(1,(COUNTA(W41!$C$9:$I$18)-COUNTIF(W41!$C$9:$I$18,"✗"))/SUM('Start Here'!$E$11:$E$20))) | E42: =IF(OR(W42!$C$7>TODAY(),SUM('Start Here'!$E$11:$E$20)=0),"",MIN(1,(COUNTA(W42!$C$9:$I$18)-COUNTIF(W42!$C$9:$I$18,"✗"))/SUM('Start Here'!$E$11:$E$20))) | F42: =IF(OR(W43!$C$7>TODAY(),SUM('Start Here'!$E$11:$E$20)=0),"",MIN(1,(COUNTA(W43!$C$9:$I$18)-COUNTIF(W43!$C$9:$I$18,"✗"))/SUM('Start Here'!$E$11:$E$20))) | G42: =IF(OR(W44!$C$7>TODAY(),SUM('Start Here'!$E$11:$E$20)=0),"",MIN(1,(COUNTA(W44!$C$9:$I$18)-COUNTIF(W44!$C$9:$I$18,"✗"))/SUM('Start Here'!$E$11:$E$20))) | H42: =IF(OR(W45!$C$7>TODAY(),SUM('Start Here'!$E$11:$E$20)=0),"",MIN(1,(COUNTA(W45!$C$9:$I$18)-COUNTIF(W45!$C$9:$I$18,"✗"))/SUM('Start Here'!$E$11:$E$20))) | I42: =IF(OR(W46!$C$7>TODAY(),SUM('Start Here'!$E$11:$E$20)=0),"",MIN(1,(COUNTA(W46!$C$9:$I$18)-COUNTIF(W46!$C$9:$I$18,"✗"))/SUM('Start Here'!$E$11:$E$20))) | J42: =IF(OR(W47!$C$7>TODAY(),SUM('Start Here'!$E$11:$E$20)=0),"",MIN(1,(COUNTA(W47!$C$9:$I$18)-COUNTIF(W47!$C$9:$I$18,"✗"))/SUM('Start Here'!$E$11:$E$20))) | K42: =IF(OR(W48!$C$7>TODAY(),SUM('Start Here'!$E$11:$E$20)=0),"",MIN(1,(COUNTA(W48!$C$9:$I$18)-COUNTIF(W48!$C$9:$I$18,"✗"))/SUM('Start Here'!$E$11:$E$20))) | L42: =IF(OR(W49!$C$7>TODAY(),SUM('Start Here'!$E$11:$E$20)=0),"",MIN(1,(COUNTA(W49!$C$9:$I$18)-COUNTIF(W49!$C$9:$I$18,"✗"))/SUM('Start Here'!$E$11:$E$20))) | M42: =IF(OR(W50!$C$7>TODAY(),SUM('Start Here'!$E$11:$E$20)=0),"",MIN(1,(COUNTA(W50!$C$9:$I$18)-COUNTIF(W50!$C$9:$I$18,"✗"))/SUM('Start Here'!$E$11:$E$20))) | N42: =IF(OR(W51!$C$7>TODAY(),SUM('Start Here'!$E$11:$E$20)=0),"",MIN(1,(COUNTA(W51!$C$9:$I$18)-COUNTIF(W51!$C$9:$I$18,"✗"))/SUM('Start Here'!$E$11:$E$20))) | O42: =IF(OR(W52!$C$7>TODAY(),SUM('Start Here'!$E$11:$E$20)=0),"",MIN(1,(COUNTA(W52!$C$9:$I$18)-COUNTIF(W52!$C$9:$I$18,"✗"))/SUM('Start Here'!$E$11:$E$20)))
C43: =W40!$C$7 | D43: =W41!$C$7 | E43: =W42!$C$7 | F43: =W43!$C$7 | G43: =W44!$C$7 | H43: =W45!$C$7 | I43: =W46!$C$7 | J43: =W47!$C$7 | K43: =W48!$C$7 | L43: =W49!$C$7 | M43: =W50!$C$7 | N43: =W51!$C$7 | O43: =W52!$C$7
C46: Miss a day and the streak resets. That is the point — it is the only rule the system has.

Sheet W01
B2: MOMENTUM · WEEKLY HABIT SYSTEM
B3: WEEK 01 | K3: =TEXT(C7,"d mmm")&" – "&TEXT(I7,"d mmm yyyy")
B4: ◀ START HERE | K4: ◆ DASHBOARD | M4: WEEK 02 ▶
B6: HABIT | C6: MON | D6: TUE | E6: WED | F6: THU | G6: FRI | H6: SAT | I6: SUN | K6: DONE | L6: GOAL | M6: HIT | N6: STREAK
C7: ='Start Here'!$E$6 | D7: ='Start Here'!$E$6+1 | E7: ='Start Here'!$E$6+2 | F7: ='Start Here'!$E$6+3 | G7: ='Start Here'!$E$6+4 | H7: ='Start Here'!$E$6+5 | I7: ='Start Here'!$E$6+6
B9: =IF('Start Here'!C11="","",'Start Here'!C11) | K9: =IF($B9="","",COUNTA(C9:I9)-COUNTIF(C9:I9,"✗")) | L9: =IF('Start Here'!E11="","",'Start Here'!E11) | M9: =IF(OR($B9="",$L9=""),"",IF($K9>=$L9,"✓","")) | N9: =IF($B9="","",IF($C$7>TODAY(),"",IF(AND($C$7<=TODAY(),$I$7>=TODAY()),Engine!$AA$2,IFERROR(LOOKUP(2,1/(Engine!$A$3:$A$366<=$I$7),Engine!$O$3:$O$366),0))))
B10: =IF('Start Here'!C12="","",'Start Here'!C12) | K10: =IF($B10="","",COUNTA(C10:I10)-COUNTIF(C10:I10,"✗")) | L10: =IF('Start Here'!E12="","",'Start Here'!E12) | M10: =IF(OR($B10="",$L10=""),"",IF($K10>=$L10,"✓","")) | N10: =IF($B10="","",IF($C$7>TODAY(),"",IF(AND($C$7<=TODAY(),$I$7>=TODAY()),Engine!$AA$3,IFERROR(LOOKUP(2,1/(Engine!$A$3:$A$366<=$I$7),Engine!$P$3:$P$366),0))))
B11: =IF('Start Here'!C13="","",'Start Here'!C13) | K11: =IF($B11="","",COUNTA(C11:I11)-COUNTIF(C11:I11,"✗")) | L11: =IF('Start Here'!E13="","",'Start Here'!E13) | M11: =IF(OR($B11="",$L11=""),"",IF($K11>=$L11,"✓","")) | N11: =IF($B11="","",IF($C$7>TODAY(),"",IF(AND($C$7<=TODAY(),$I$7>=TODAY()),Engine!$AA$4,IFERROR(LOOKUP(2,1/(Engine!$A$3:$A$366<=$I$7),Engine!$Q$3:$Q$366),0))))
B12: =IF('Start Here'!C14="","",'Start Here'!C14) | K12: =IF($B12="","",COUNTA(C12:I12)-COUNTIF(C12:I12,"✗")) | L12: =IF('Start Here'!E14="","",'Start Here'!E14) | M12: =IF(OR($B12="",$L12=""),"",IF($K12>=$L12,"✓","")) | N12: =IF($B12="","",IF($C$7>TODAY(),"",IF(AND($C$7<=TODAY(),$I$7>=TODAY()),Engine!$AA$5,IFERROR(LOOKUP(2,1/(Engine!$A$3:$A$366<=$I$7),Engine!$R$3:$R$366),0))))
B13: =IF('Start Here'!C15="","",'Start Here'!C15) | K13: =IF($B13="","",COUNTA(C13:I13)-COUNTIF(C13:I13,"✗")) | L13: =IF('Start Here'!E15="","",'Start Here'!E15) | M13: =IF(OR($B13="",$L13=""),"",IF($K13>=$L13,"✓","")) | N13: =IF($B13="","",IF($C$7>TODAY(),"",IF(AND($C$7<=TODAY(),$I$7>=TODAY()),Engine!$AA$6,IFERROR(LOOKUP(2,1/(Engine!$A$3:$A$366<=$I$7),Engine!$S$3:$S$366),0))))
B14: =IF('Start Here'!C16="","",'Start Here'!C16) | K14: =IF($B14="","",COUNTA(C14:I14)-COUNTIF(C14:I14,"✗")) | L14: =IF('Start Here'!E16="","",'Start Here'!E16) | M14: =IF(OR($B14="",$L14=""),"",IF($K14>=$L14,"✓","")) | N14: =IF($B14="","",IF($C$7>TODAY(),"",IF(AND($C$7<=TODAY(),$I$7>=TODAY()),Engine!$AA$7,IFERROR(LOOKUP(2,1/(Engine!$A$3:$A$366<=$I$7),Engine!$T$3:$T$366),0))))
B15: =IF('Start Here'!C17="","",'Start Here'!C17) | K15: =IF($B15="","",COUNTA(C15:I15)-COUNTIF(C15:I15,"✗")) | L15: =IF('Start Here'!E17="","",'Start Here'!E17) | M15: =IF(OR($B15="",$L15=""),"",IF($K15>=$L15,"✓","")) | N15: =IF($B15="","",IF($C$7>TODAY(),"",IF(AND($C$7<=TODAY(),$I$7>=TODAY()),Engine!$AA$8,IFERROR(LOOKUP(2,1/(Engine!$A$3:$A$366<=$I$7),Engine!$U$3:$U$366),0))))
B16: =IF('Start Here'!C18="","",'Start Here'!C18) | K16: =IF($B16="","",COUNTA(C16:I16)-COUNTIF(C16:I16,"✗")) | L16: =IF('Start Here'!E18="","",'Start Here'!E18) | M16: =IF(OR($B16="",$L16=""),"",IF($K16>=$L16,"✓","")) | N16: =IF($B16="","",IF($C$7>TODAY(),"",IF(AND($C$7<=TODAY(),$I$7>=TODAY()),Engine!$AA$9,IFERROR(LOOKUP(2,1/(Engine!$A$3:$A$366<=$I$7),Engine!$V$3:$V$366),0))))
B17: =IF('Start Here'!C19="","",'Start Here'!C19) | K17: =IF($B17="","",COUNTA(C17:I17)-COUNTIF(C17:I17,"✗")) | L17: =IF('Start Here'!E19="","",'Start Here'!E19) | M17: =IF(OR($B17="",$L17=""),"",IF($K17>=$L17,"✓","")) | N17: =IF($B17="","",IF($C$7>TODAY(),"",IF(AND($C$7<=TODAY(),$I$7>=TODAY()),Engine!$AA$10,IFERROR(LOOKUP(2,1/(Engine!$A$3:$A$366<=$I$7),Engine!$W$3:$W$366),0))))
B18: =IF('Start Here'!C20="","",'Start Here'!C20) | K18: =IF($B18="","",COUNTA(C18:I18)-COUNTIF(C18:I18,"✗")) | L18: =IF('Start Here'!E20="","",'Start Here'!E20) | M18: =IF(OR($B18="",$L18=""),"",IF($K18>=$L18,"✓","")) | N18: =IF($B18="","",IF($C$7>TODAY(),"",IF(AND($C$7<=TODAY(),$I$7>=TODAY()),Engine!$AA$11,IFERROR(LOOKUP(2,1/(Engine!$A$3:$A$366<=$I$7),Engine!$X$3:$X$366),0))))
B20: DAILY TOTAL | C20: =IF(C$7>TODAY(),"",COUNTA(C9:C18)-COUNTIF(C9:C18,"✗")) | D20: =IF(D$7>TODAY(),"",COUNTA(D9:D18)-COUNTIF(D9:D18,"✗")) | E20: =IF(E$7>TODAY(),"",COUNTA(E9:E18)-COUNTIF(E9:E18,"✗")) | F20: =IF(F$7>TODAY(),"",COUNTA(F9:F18)-COUNTIF(F9:F18,"✗")) | G20: =IF(G$7>TODAY(),"",COUNTA(G9:G18)-COUNTIF(G9:G18,"✗")) | H20: =IF(H$7>TODAY(),"",COUNTA(H9:H18)-COUNTIF(H9:H18,"✗")) | I20: =IF(I$7>TODAY(),"",COUNTA(I9:I18)-COUNTIF(I9:I18,"✗")) | K20: =SUM(K9:K18) | L20: =SUM(L9:L18)
B22: WEEK SCORE | C22: =IF($C$7>TODAY(),"",IF(SUM($L$9:$L$18)=0,"",MIN(1,SUM($K$9:$K$18)/SUM($L$9:$L$18)))) | F22: PERFECT DAYS | H22: =IF(OR($C$7>TODAY(),SUMPRODUCT(--($B$9:$B$18<>""))=0),"",SUMPRODUCT(--($C$20:$I$20=SUMPRODUCT(--($B$9:$B$18<>""))))) | K22: TOP STREAK | M22: =IF(COUNT($N$9:$N$18)=0,"",MAX($N$9:$N$18))
B24: FOCUS THIS WEEK
B26: NOTES

Sheet W02
B2: MOMENTUM · WEEKLY HABIT SYSTEM
B3: WEEK 02 | K3: =TEXT(C7,"d mmm")&" – "&TEXT(I7,"d mmm yyyy")
B4: ◀ WEEK 01 | K4: ◆ DASHBOARD | M4: WEEK 03 ▶
B6: HABIT | C6: MON | D6: TUE | E6: WED | F6: THU | G6: FRI | H6: SAT | I6: SUN | K6: DONE | L6: GOAL | M6: HIT | N6: STREAK
C7: ='Start Here'!$E$6+7 | D7: ='Start Here'!$E$6+8 | E7: ='Start Here'!$E$6+9 | F7: ='Start Here'!$E$6+10 | G7: ='Start Here'!$E$6+11 | H7: ='Start Here'!$E$6+12 | I7: ='Start Here'!$E$6+13
B9: =IF('Start Here'!C11="","",'Start Here'!C11) | K9: =IF($B9="","",COUNTA(C9:I9)-COUNTIF(C9:I9,"✗")) | L9: =IF('Start Here'!E11="","",'Start Here'!E11) | M9: =IF(OR($B9="",$L9=""),"",IF($K9>=$L9,"✓","")) | N9: =IF($B9="","",IF($C$7>TODAY(),"",IF(AND($C$7<=TODAY(),$I$7>=TODAY()),Engine!$AA$2,IFERROR(LOOKUP(2,1/(Engine!$A$3:$A$366<=$I$7),Engine!$O$3:$O$366),0))))
B10: =IF('Start Here'!C12="","",'Start Here'!C12) | K10: =IF($B10="","",COUNTA(C10:I10)-COUNTIF(C10:I10,"✗")) | L10: =IF('Start Here'!E12="","",'Start Here'!E12) | M10: =IF(OR($B10="",$L10=""),"",IF($K10>=$L10,"✓","")) | N10: =IF($B10="","",IF($C$7>TODAY(),"",IF(AND($C$7<=TODAY(),$I$7>=TODAY()),Engine!$AA$3,IFERROR(LOOKUP(2,1/(Engine!$A$3:$A$366<=$I$7),Engine!$P$3:$P$366),0))))
B11: =IF('Start Here'!C13="","",'Start Here'!C13) | K11: =IF($B11="","",COUNTA(C11:I11)-COUNTIF(C11:I11,"✗")) | L11: =IF('Start Here'!E13="","",'Start Here'!E13) | M11: =IF(OR($B11="",$L11=""),"",IF($K11>=$L11,"✓","")) | N11: =IF($B11="","",IF($C$7>TODAY(),"",IF(AND($C$7<=TODAY(),$I$7>=TODAY()),Engine!$AA$4,IFERROR(LOOKUP(2,1/(Engine!$A$3:$A$366<=$I$7),Engine!$Q$3:$Q$366),0))))
B12: =IF('Start Here'!C14="","",'Start Here'!C14) | K12: =IF($B12="","",COUNTA(C12:I12)-COUNTIF(C12:I12,"✗")) | L12: =IF('Start Here'!E14="","",'Start Here'!E14) | M12: =IF(OR($B12="",$L12=""),"",IF($K12>=$L12,"✓","")) | N12: =IF($B12="","",IF($C$7>TODAY(),"",IF(AND($C$7<=TODAY(),$I$7>=TODAY()),Engine!$AA$5,IFERROR(LOOKUP(2,1/(Engine!$A$3:$A$366<=$I$7),Engine!$R$3:$R$366),0))))
B13: =IF('Start Here'!C15="","",'Start Here'!C15) | K13: =IF($B13="","",COUNTA(C13:I13)-COUNTIF(C13:I13,"✗")) | L13: =IF('Start Here'!E15="","",'Start Here'!E15) | M13: =IF(OR($B13="",$L13=""),"",IF($K13>=$L13,"✓","")) | N13: =IF($B13="","",IF($C$7>TODAY(),"",IF(AND($C$7<=TODAY(),$I$7>=TODAY()),Engine!$AA$6,IFERROR(LOOKUP(2,1/(Engine!$A$3:$A$366<=$I$7),Engine!$S$3:$S$366),0))))
B14: =IF('Start Here'!C16="","",'Start Here'!C16) | K14: =IF($B14="","",COUNTA(C14:I14)-COUNTIF(C14:I14,"✗")) | L14: =IF('Start Here'!E16="","",'Start Here'!E16) | M14: =IF(OR($B14="",$L14=""),"",IF($K14>=$L14,"✓","")) | N14: =IF($B14="","",IF($C$7>TODAY(),"",IF(AND($C$7<=TODAY(),$I$7>=TODAY()),Engine!$AA$7,IFERROR(LOOKUP(2,1/(Engine!$A$3:$A$366<=$I$7),Engine!$T$3:$T$366),0))))
B15: =IF('Start Here'!C17="","",'Start Here'!C17) | K15: =IF($B15="","",COUNTA(C15:I15)-COUNTIF(C15:I15,"✗")) | L15: =IF('Start Here'!E17="","",'Start Here'!E17) | M15: =IF(OR($B15="",$L15=""),"",IF($K15>=$L15,"✓","")) | N15: =IF($B15="","",IF($C$7>TODAY(),"",IF(AND($C$7<=TODAY(),$I$7>=TODAY()),Engine!$AA$8,IFERROR(LOOKUP(2,1/(Engine!$A$3:$A$366<=$I$7),Engine!$U$3:$U$366),0))))
B16: =IF('Start Here'!C18="","",'Start Here'!C18) | K16: =IF($B16="","",COUNTA(C16:I16)-COUNTIF(C16:I16,"✗")) | L16: =IF('Start Here'!E18="","",'Start Here'!E18) | M16: =IF(OR($B16="",$L16=""),"",IF($K16>=$L16,"✓","")) | N16: =IF($B16="","",IF($C$7>TODAY(),"",IF(AND($C$7<=TODAY(),$I$7>=TODAY()),Engine!$AA$9,IFERROR(LOOKUP(2,1/(Engine!$A$3:$A$366<=$I$7),Engine!$V$3:$V$366),0))))
B17: =IF('Start Here'!C19="","",'Start Here'!C19) | K17: =IF($B17="","",COUNTA(C17:I17)-COUNTIF(C17:I17,"✗")) | L17: =IF('Start Here'!E19="","",'Start Here'!E19) | M17: =IF(OR($B17="",$L17=""),"",IF($K17>=$L17,"✓","")) | N17: =IF($B17="","",IF($C$7>TODAY(),"",IF(AND($C$7<=TODAY(),$I$7>=TODAY()),Engine!$AA$10,IFERROR(LOOKUP(2,1/(Engine!$A$3:$A$366<=$I$7),Engine!$W$3:$W$366),0))))
B18: =IF('Start Here'!C20="","",'Start Here'!C20) | K18: =IF($B18="","",COUNTA(C18:I18)-COUNTIF(C18:I18,"✗")) | L18: =IF('Start Here'!E20="","",'Start Here'!E20) | M18: =IF(OR($B18="",$L18=""),"",IF($K18>=$L18,"✓","")) | N18: =IF($B18="","",IF($C$7>TODAY(),"",IF(AND($C$7<=TODAY(),$I$7>=TODAY()),Engine!$AA$11,IFERROR(LOOKUP(2,1/(Engine!$A$3:$A$366<=$I$7),Engine!$X$3:$X$366),0))))
B20: DAILY TOTAL | C20: =IF(C$7>TODAY(),"",COUNTA(C9:C18)-COUNTIF(C9:C18,"✗")) | D20: =IF(D$7>TODAY(),"",COUNTA(D9:D18)-COUNTIF(D9:D18,"✗")) | E20: =IF(E$7>TODAY(),"",COUNTA(E9:E18)-COUNTIF(E9:E18,"✗")) | F20: =IF(F$7>TODAY(),"",COUNTA(F9:F18)-COUNTIF(F9:F18,"✗")) | G20: =IF(G$7>TODAY(),"",COUNTA(G9:G18)-COUNTIF(G9:G18,"✗")) | H20: =IF(H$7>TODAY(),"",COUNTA(H9:H18)-COUNTIF(H9:H18,"✗")) | I20: =IF(I$7>TODAY(),"",COUNTA(I9:I18)-COUNTIF(I9:I18,"✗")) | K20: =SUM(K9:K18) | L20: =SUM(L9:L18)
B22: WEEK SCORE | C22: =IF($C$7>TODAY(),"",IF(SUM($L$9:$L$18)=0,"",MIN(1,SUM($K$9:$K$18)/SUM($L$9:$L$18)))) | F22: PERFECT DAYS | H22: =IF(OR($C$7>TODAY(),SUMPRODUCT(--($B$9:$B$18<>""))=0),"",SUMPRODUCT(--($C$20:$I$20=SUMPRODUCT(--($B$9:$B$18<>""))))) | K22: TOP STREAK | M22: =IF(COUNT($N$9:$N$18)=0,"",MAX($N$9:$N$18))
B24: FOCUS THIS WEEK
B26: NOTES

Sheet W03
B2: MOMENTUM · WEEKLY HABIT SYSTEM
B3: WEEK 03 | K3: =TEXT(C7,"d mmm")&" – "&TEXT(I7,"d mmm yyyy")
B4: ◀ WEEK 02 | K4: ◆ DASHBOARD | M4: WEEK 04 ▶
B6: HABIT | C6: MON | D6: TUE | E6: WED | F6: THU | G6: FRI | H6: SAT | I6: SUN | K6: DONE | L6: GOAL | M6: HIT | N6: STREAK
C7: ='Start Here'!$E$6+14 | D7: ='Start Here'!$E$6+15 | E7: ='Start Here'!$E$6+16 | F7: ='Start Here'!$E$6+17 | G7: ='Start Here'!$E$6+18 | H7: ='Start Here'!$E$6+19 | I7: ='Start Here'!$E$6+20
B9: =IF('Start Here'!C11="","",'Start Here'!C11) | K9: =IF($B9="","",COUNTA(C9:I9)-COUNTIF(C9:I9,"✗")) | L9: =IF('Start Here'!E11="","",'Start Here'!E11) | M9: =IF(OR($B9="",$L9=""),"",IF($K9>=$L9,"✓","")) | N9: =IF($B9="","",IF($C$7>TODAY(),"",IF(AND($C$7<=TODAY(),$I$7>=TODAY()),Engine!$AA$2,IFERROR(LOOKUP(2,1/(Engine!$A$3:$A$366<=$I$7),Engine!$O$3:$O$366),0))))
B10: =IF('Start Here'!C12="","",'Start Here'!C12) | K10: =IF($B10="","",COUNTA(C10:I10)-COUNTIF(C10:I10,"✗")) | L10: =IF('Start Here'!E12="","",'Start Here'!E12) | M10: =IF(OR($B10="",$L10=""),"",IF($K10>=$L10,"✓","")) | N10: =IF($B10="","",IF($C$7>TODAY(),"",IF(AND($C$7<=TODAY(),$I$7>=TODAY()),Engine!$AA$3,IFERROR(LOOKUP(2,1/(Engine!$A$3:$A$366<=$I$7),Engine!$P$3:$P$366),0))))
B11: =IF('Start Here'!C13="","",'Start Here'!C13) | K11: =IF($B11="","",COUNTA(C11:I11)-COUNTIF(C11:I11,"✗")) | L11: =IF('Start Here'!E13="","",'Start Here'!E13) | M11: =IF(OR($B11="",$L11=""),"",IF($K11>=$L11,"✓","")) | N11: =IF($B11="","",IF($C$7>TODAY(),"",IF(AND($C$7<=TODAY(),$I$7>=TODAY()),Engine!$AA$4,IFERROR(LOOKUP(2,1/(Engine!$A$3:$A$366<=$I$7),Engine!$Q$3:$Q$366),0))))
B12: =IF('Start Here'!C14="","",'Start Here'!C14) | K12: =IF($B12="","",COUNTA(C12:I12)-COUNTIF(C12:I12,"✗")) | L12: =IF('Start Here'!E14="","",'Start Here'!E14) | M12: =IF(OR($B12="",$L12=""),"",IF($K12>=$L12,"✓","")) | N12: =IF($B12="","",IF($C$7>TODAY(),"",IF(AND($C$7<=TODAY(),$I$7>=TODAY()),Engine!$AA$5,IFERROR(LOOKUP(2,1/(Engine!$A$3:$A$366<=$I$7),Engine!$R$3:$R$366),0))))
B13: =IF('Start Here'!C15="","",'Start Here'!C15) | K13: =IF($B13="","",COUNTA(C13:I13)-COUNTIF(C13:I13,"✗")) | L13: =IF('Start Here'!E15="","",'Start Here'!E15) | M13: =IF(OR($B13="",$L13=""),"",IF($K13>=$L13,"✓","")) | N13: =IF($B13="","",IF($C$7>TODAY(),"",IF(AND($C$7<=TODAY(),$I$7>=TODAY()),Engine!$AA$6,IFERROR(LOOKUP(2,1/(Engine!$A$3:$A$366<=$I$7),Engine!$S$3:$S$366),0))))
B14: =IF('Start Here'!C16="","",'Start Here'!C16) | K14: =IF($B14="","",COUNTA(C14:I14)-COUNTIF(C14:I14,"✗")) | L14: =IF('Start Here'!E16="","",'Start Here'!E16) | M14: =IF(OR($B14="",$L14=""),"",IF($K14>=$L14,"✓","")) | N14: =IF($B14="","",IF($C$7>TODAY(),"",IF(AND($C$7<=TODAY(),$I$7>=TODAY()),Engine!$AA$7,IFERROR(LOOKUP(2,1/(Engine!$A$3:$A$366<=$I$7),Engine!$T$3:$T$366),0))))
B15: =IF('Start Here'!C17="","",'Start Here'!C17) | K15: =IF($B15="","",COUNTA(C15:I15)-COUNTIF(C15:I15,"✗")) | L15: =IF('Start Here'!E17="","",'Start Here'!E17) | M15: =IF(OR($B15="",$L15=""),"",IF($K15>=$L15,"✓","")) | N15: =IF($B15="","",IF($C$7>TODAY(),"",IF(AND($C$7<=TODAY(),$I$7>=TODAY()),Engine!$AA$8,IFERROR(LOOKUP(2,1/(Engine!$A$3:$A$366<=$I$7),Engine!$U$3:$U$366),0))))
B16: =IF('Start Here'!C18="","",'Start Here'!C18) | K16: =IF($B16="","",COUNTA(C16:I16)-COUNTIF(C16:I16,"✗")) | L16: =IF('Start Here'!E18="","",'Start Here'!E18) | M16: =IF(OR($B16="",$L16=""),"",IF($K16>=$L16,"✓","")) | N16: =IF($B16="","",IF($C$7>TODAY(),"",IF(AND($C$7<=TODAY(),$I$7>=TODAY()),Engine!$AA$9,IFERROR(LOOKUP(2,1/(Engine!$A$3:$A$366<=$I$7),Engine!$V$3:$V$366),0))))
B17: =IF('Start Here'!C19="","",'Start Here'!C19) | K17: =IF($B17="","",COUNTA(C17:I17)-COUNTIF(C17:I17,"✗")) | L17: =IF('Start Here'!E19="","",'Start Here'!E19) | M17: =IF(OR($B17="",$L17=""),"",IF($K17>=$L17,"✓","")) | N17: =IF($B17="","",IF($C$7>TODAY(),"",IF(AND($C$7<=TODAY(),$I$7>=TODAY()),Engine!$AA$10,IFERROR(LOOKUP(2,1/(Engine!$A$3:$A$366<=$I$7),Engine!$W$3:$W$366),0))))
B18: =IF('Start Here'!C20="","",'Start Here'!C20) | K18: =IF($B18="","",COUNTA(C18:I18)-COUNTIF(C18:I18,"✗")) | L18: =IF('Start Here'!E20="","",'Start Here'!E20) | M18: =IF(OR($B18="",$L18=""),"",IF($K18>=$L18,"✓","")) | N18: =IF($B18="","",IF($C$7>TODAY(),"",IF(AND($C$7<=TODAY(),$I$7>=TODAY()),Engine!$AA$11,IFERROR(LOOKUP(2,1/(Engine!$A$3:$A$366<=$I$7),Engine!$X$3:$X$366),0))))
B20: DAILY TOTAL | C20: =IF(C$7>TODAY(),"",COUNTA(C9:C18)-COUNTIF(C9:C18,"✗")) | D20: =IF(D$7>TODAY(),"",COUNTA(D9:D18)-COUNTIF(D9:D18,"✗")) | E20: =IF(E$7>TODAY(),"",COUNTA(E9:E18)-COUNTIF(E9:E18,"✗")) | F20: =IF(F$7>TODAY(),"",COUNTA(F9:F18)-COUNTIF(F9:F18,"✗")) | G20: =IF(G$7>TODAY(),"",COUNTA(G9:G18)-COUNTIF(G9:G18,"✗")) | H20: =IF(H$7>TODAY(),"",COUNTA(H9:H18)-COUNTIF(H9:H18,"✗")) | I20: =IF(I$7>TODAY(),"",COUNTA(I9:I18)-COUNTIF(I9:I18,"✗")) | K20: =SUM(K9:K18) | L20: =SUM(L9:L18)
B22: WEEK SCORE | C22: =IF($C$7>TODAY(),"",IF(SUM($L$9:$L$18)=0,"",MIN(1,SUM($K$9:$K$18)/SUM($L$9:$L$18)))) | F22: PERFECT DAYS | H22: =IF(OR($C$7>TODAY(),SUMPRODUCT(--($B$9:$B$18<>""))=0),"",SUMPRODUCT(--($C$20:$I$20=SUMPRODUCT(--($B$9:$B$18<>""))))) | K22: TOP STREAK | M22: =IF(COUNT($N$9:$N$18)=0,"",MAX($N$9:$N$18))
B24: FOCUS THIS WEEK
B26: NOTES

Sheet W04
B2: MOMENTUM · WEEKLY HABIT SYSTEM
B3: WEEK 04 | K3: =TEXT(C7,"d mmm")&" – "&TEXT(I7,"d mmm yyyy")
B4: ◀ WEEK 03 | K4: ◆ DASHBOARD | M4: WEEK 05 ▶
B6: HABIT | C6: MON | D6: TUE | E6: WED | F6: THU | G6: FRI | H6: SAT | I6: SUN | K6: DONE | L6: GOAL | M6: HIT | N6: STREAK
C7: ='Start Here'!$E$6+21 | D7: ='Start Here'!$E$6+22 | E7: ='Start Here'!$E$6+23 | F7: ='Start Here'!$E$6+24 | G7: ='Start Here'!$E$6+25 | H7: ='Start Here'!$E$6+26 | I7: ='Start Here'!$E$6+27
B9: =IF('Start Here'!C11="","",'Start Here'!C11) | K9: =IF($B9="","",COUNTA(C9:I9)-COUNTIF(C9:I9,"✗")) | L9: =IF('Start Here'!E11="","",'Start Here'!E11) | M9: =IF(OR($B9="",$L9=""),"",IF($K9>=$L9,"✓","")) | N9: =IF($B9="","",IF($C$7>TODAY(),"",IF(AND($C$7<=TODAY(),$I$7>=TODAY()),Engine!$AA$2,IFERROR(LOOKUP(2,1/(Engine!$A$3:$A$366<=$I$7),Engine!$O$3:$O$366),0))))
B10: =IF('Start Here'!C12="","",'Start Here'!C12) | K10: =IF($B10="","",COUNTA(C10:I10)-COUNTIF(C10:I10,"✗")) | L10: =IF('Start Here'!E12="","",'Start Here'!E12) | M10: =IF(OR($B10="",$L10=""),"",IF($K10>=$L10,"✓","")) | N10: =IF($B10="","",IF($C$7>TODAY(),"",IF(AND($C$7<=TODAY(),$I$7>=TODAY()),Engine!$AA$3,IFERROR(LOOKUP(2,1/(Engine!$A$3:$A$366<=$I$7),Engine!$P$3:$P$366),0))))
B11: =IF('Start Here'!C13="","",'Start Here'!C13) | K11: =IF($B11="","",COUNTA(C11:I11)-COUNTIF(C11:I11,"✗")) | L11: =IF('Start Here'!E13="","",'Start Here'!E13) | M11: =IF(OR($B11="",$L11=""),"",IF($K11>=$L11,"✓","")) | N11: =IF($B11="","",IF($C$7>TODAY(),"",IF(AND($C$7<=TODAY(),$I$7>=TODAY()),Engine!$AA$4,IFERROR(LOOKUP(2,1/(Engine!$A$3:$A$366<=$I$7),Engine!$Q$3:$Q$366),0))))
B12: =IF('Start Here'!C14="","",'Start Here'!C14) | K12: =IF($B12="","",COUNTA(C12:I12)-COUNTIF(C12:I12,"✗")) | L12: =IF('Start Here'!E14="","",'Start Here'!E14) | M12: =IF(OR($B12="",$L12=""),"",IF($K12>=$L12,"✓","")) | N12: =IF($B12="","",IF($C$7>TODAY(),"",IF(AND($C$7<=TODAY(),$I$7>=TODAY()),Engine!$AA$5,IFERROR(LOOKUP(2,1/(Engine!$A$3:$A$366<=$I$7),Engine!$R$3:$R$366),0))))
B13: =IF('Start Here'!C15="","",'Start Here'!C15) | K13: =IF($B13="","",COUNTA(C13:I13)-COUNTIF(C13:I13,"✗")) | L13: =IF('Start Here'!E15="","",'Start Here'!E15) | M13: =IF(OR($B13="",$L13=""),"",IF($K13>=$L13,"✓","")) | N13: =IF($B13="","",IF($C$7>TODAY(),"",IF(AND($C$7<=TODAY(),$I$7>=TODAY()),Engine!$AA$6,IFERROR(LOOKUP(2,1/(Engine!$A$3:$A$366<=$I$7),Engine!$S$3:$S$366),0))))
B14: =IF('Start Here'!C16="","",'Start Here'!C16) | K14: =IF($B14="","",COUNTA(C14:I14)-COUNTIF(C14:I14,"✗")) | L14: =IF('Start Here'!E16="","",'Start Here'!E16) | M14: =IF(OR($B14="",$L14=""),"",IF($K14>=$L14,"✓","")) | N14: =IF($B14="","",IF($C$7>TODAY(),"",IF(AND($C$7<=TODAY(),$I$7>=TODAY()),Engine!$AA$7,IFERROR(LOOKUP(2,1/(Engine!$A$3:$A$366<=$I$7),Engine!$T$3:$T$366),0))))
B15: =IF('Start Here'!C17="","",'Start Here'!C17) | K15: =IF($B15="","",COUNTA(C15:I15)-COUNTIF(C15:I15,"✗")) | L15: =IF('Start Here'!E17="","",'Start Here'!E17) | M15: =IF(OR($B15="",$L15=""),"",IF($K15>=$L15,"✓","")) | N15: =IF($B15="","",IF($C$7>TODAY(),"",IF(AND($C$7<=TODAY(),$I$7>=TODAY()),Engine!$AA$8,IFERROR(LOOKUP(2,1/(Engine!$A$3:$A$366<=$I$7),Engine!$U$3:$U$366),0))))
B16: =IF('Start Here'!C18="","",'Start Here'!C18) | K16: =IF($B16="","",COUNTA(C16:I16)-COUNTIF(C16:I16,"✗")) | L16: =IF('Start Here'!E18="","",'Start Here'!E18) | M16: =IF(OR($B16="",$L16=""),"",IF($K16>=$L16,"✓","")) | N16: =IF($B16="","",IF($C$7>TODAY(),"",IF(AND($C$7<=TODAY(),$I$7>=TODAY()),Engine!$AA$9,IFERROR(LOOKUP(2,1/(Engine!$A$3:$A$366<=$I$7),Engine!$V$3:$V$366),0))))
B17: =IF('Start Here'!C19="","",'Start Here'!C19) | K17: =IF($B17="","",COUNTA(C17:I17)-COUNTIF(C17:I17,"✗")) | L17: =IF('Start Here'!E19="","",'Start Here'!E19) | M17: =IF(OR($B17="",$L17=""),"",IF($K17>=$L17,"✓","")) | N17: =IF($B17="","",IF($C$7>TODAY(),"",IF(AND($C$7<=TODAY(),$I$7>=TODAY()),Engine!$AA$10,IFERROR(LOOKUP(2,1/(Engine!$A$3:$A$366<=$I$7),Engine!$W$3:$W$366),0))))
B18: =IF('Start Here'!C20="","",'Start Here'!C20) | K18: =IF($B18="","",COUNTA(C18:I18)-COUNTIF(C18:I18,"✗")) | L18: =IF('Start Here'!E20="","",'Start Here'!E20) | M18: =IF(OR($B18="",$L18=""),"",IF($K18>=$L18,"✓","")) | N18: =IF($B18="","",IF($C$7>TODAY(),"",IF(AND($C$7<=TODAY(),$I$7>=TODAY()),Engine!$AA$11,IFERROR(LOOKUP(2,1/(Engine!$A$3:$A$366<=$I$7),Engine!$X$3:$X$366),0))))
B20: DAILY TOTAL | C20: =IF(C$7>TODAY(),"",COUNTA(C9:C18)-COUNTIF(C9:C18,"✗")) | D20: =IF(D$7>TODAY(),"",COUNTA(D9:D18)-COUNTIF(D9:D18,"✗")) | E20: =IF(E$7>TODAY(),"",COUNTA(E9:E18)-COUNTIF(E9:E18,"✗")) | F20: =IF(F$7>TODAY(),"",COUNTA(F9:F18)-COUNTIF(F9:F18,"✗")) | G20: =IF(G$7>TODAY(),"",COUNTA(G9:G18)-COUNTIF(G9:G18,"✗")) | H20: =IF(H$7>TODAY(),"",COUNTA(H9:H18)-COUNTIF(H9:H18,"✗")) | I20: =IF(I$7>TODAY(),"",COUNTA(I9:I18)-COUNTIF(I9:I18,"✗")) | K20: =SUM(K9:K18) | L20: =SUM(L9:L18)
B22: WEEK SCORE | C22: =IF($C$7>TODAY(),"",IF(SUM($L$9:$L$18)=0,"",MIN(1,SUM($K$9:$K$18)/SUM($L$9:$L$18)))) | F22: PERFECT DAYS | H22: =IF(OR($C$7>TODAY(),SUMPRODUCT(--($B$9:$B$18<>""))=0),"",SUMPRODUCT(--($C$20:$I$20=SUMPRODUCT(--($B$9:$B$18<>""))))) | K22: TOP STREAK | M22: =IF(COUNT($N$9:$N$18)=0,"",MAX($N$9:$N$18))
B24: FOCUS THIS WEEK
B26: NOTES

Sheet W05
B2: MOMENTUM · WEEKLY HABIT SYSTEM
B3: WEEK 05 | K3: =TEXT(C7,"d mmm")&" – "&TEXT(I7,"d mmm yyyy")
B4: ◀ WEEK 04 | K4: ◆ DASHBOARD | M4: WEEK 06 ▶
B6: HABIT | C6: MON | D6: TUE | E6: WED | F6: THU | G6: FRI | H6: SAT | I6: SUN | K6: DONE | L6: GOAL | M6: HIT | N6: STREAK
C7: ='Start Here'!$E$6+28 | D7: ='Start Here'!$E$6+29 | E7: ='Start Here'!$E$6+30 | F7: ='Start Here'!$E$6+31 | G7: ='Start Here'!$E$6+32 | H7: ='Start Here'!$E$6+33 | I7: ='Start Here'!$E$6+34
B9: =IF('Start Here'!C11="","",'Start Here'!C11) | K9: =IF($B9="","",COUNTA(C9:I9)-COUNTIF(C9:I9,"✗")) | L9: =IF('Start Here'!E11="","",'Start Here'!E11) | M9: =IF(OR($B9="",$L9=""),"",IF($K9>=$L9,"✓","")) | N9: =IF($B9="","",IF($C$7>TODAY(),"",IF(AND($C$7<=TODAY(),$I$7>=TODAY()),Engine!$AA$2,IFERROR(LOOKUP(2,1/(Engine!$A$3:$A$366<=$I$7),Engine!$O$3:$O$366),0))))
B10: =IF('Start Here'!C12="","",'Start Here'!C12) | K10: =IF($B10="","",COUNTA(C10:I10)-COUNTIF(C10:I10,"✗")) | L10: =IF('Start Here'!E12="","",'Start Here'!E12) | M10: =IF(OR($B10="",$L10=""),"",IF($K10>=$L10,"✓","")) | N10: =IF($B10="","",IF($C$7>TODAY(),"",IF(AND($C$7<=TODAY(),$I$7>=TODAY()),Engine!$AA$3,IFERROR(LOOKUP(2,1/(Engine!$A$3:$A$366<=$I$7),Engine!$P$3:$P$366),0))))
B11: =IF('Start Here'!C13="","",'Start Here'!C13) | K11: =IF($B11="","",COUNTA(C11:I11)-COUNTIF(C11:I11,"✗")) | L11: =IF('Start Here'!E13="","",'Start Here'!E13) | M11: =IF(OR($B11="",$L11=""),"",IF($K11>=$L11,"✓","")) | N11: =IF($B11="","",IF($C$7>TODAY(),"",IF(AND($C$7<=TODAY(),$I$7>=TODAY()),Engine!$AA$4,IFERROR(LOOKUP(2,1/(Engine!$A$3:$A$366<=$I$7),Engine!$Q$3:$Q$366),0))))
B12: =IF('Start Here'!C14="","",'Start Here'!C14) | K12: =IF($B12="","",COUNTA(C12:I12)-COUNTIF(C12:I12,"✗")) | L12: =IF('Start Here'!E14="","",'Start Here'!E14) | M12: =IF(OR($B12="",$L12=""),"",IF($K12>=$L12,"✓","")) | N12: =IF($B12="","",IF($C$7>TODAY(),"",IF(AND($C$7<=TODAY(),$I$7>=TODAY()),Engine!$AA$5,IFERROR(LOOKUP(2,1/(Engine!$A$3:$A$366<=$I$7),Engine!$R$3:$R$366),0))))
B13: =IF('Start Here'!C15="","",'Start Here'!C15) | K13: =IF($B13="","",COUNTA(C13:I13)-COUNTIF(C13:I13,"✗")) | L13: =IF('Start Here'!E15="","",'Start Here'!E15) | M13: =IF(OR($B13="",$L13=""),"",IF($K13>=$L13,"✓","")) | N13: =IF($B13="","",IF($C$7>TODAY(),"",IF(AND($C$7<=TODAY(),$I$7>=TODAY()),Engine!$AA$6,IFERROR(LOOKUP(2,1/(Engine!$A$3:$A$366<=$I$7),Engine!$S$3:$S$366),0))))
B14: =IF('Start Here'!C16="","",'Start Here'!C16) | K14: =IF($B14="","",COUNTA(C14:I14)-COUNTIF(C14:I14,"✗")) | L14: =IF('Start Here'!E16="","",'Start Here'!E16) | M14: =IF(OR($B14="",$L14=""),"",IF($K14>=$L14,"✓","")) | N14: =IF($B14="","",IF($C$7>TODAY(),"",IF(AND($C$7<=TODAY(),$I$7>=TODAY()),Engine!$AA$7,IFERROR(LOOKUP(2,1/(Engine!$A$3:$A$366<=$I$7),Engine!$T$3:$T$366),0))))
B15: =IF('Start Here'!C17="","",'Start Here'!C17) | K15: =IF($B15="","",COUNTA(C15:I15)-COUNTIF(C15:I15,"✗")) | L15: =IF('Start Here'!E17="","",'Start Here'!E17) | M15: =IF(OR($B15="",$L15=""),"",IF($K15>=$L15,"✓","")) | N15: =IF($B15="","",IF($C$7>TODAY(),"",IF(AND($C$7<=TODAY(),$I$7>=TODAY()),Engine!$AA$8,IFERROR(LOOKUP(2,1/(Engine!$A$3:$A$366<=$I$7),Engine!$U$3:$U$366),0))))
B16: =IF('Start Here'!C18="","",'Start Here'!C18) | K16: =IF($B16="","",COUNTA(C16:I16)-COUNTIF(C16:I16,"✗")) | L16: =IF('Start Here'!E18="","",'Start Here'!E18) | M16: =IF(OR($B16="",$L16=""),"",IF($K16>=$L16,"✓","")) | N16: =IF($B16="","",IF($C$7>TODAY(),"",IF(AND($C$7<=TODAY(),$I$7>=TODAY()),Engine!$AA$9,IFERROR(LOOKUP(2,1/(Engine!$A$3:$A$366<=$I$7),Engine!$V$3:$V$366),0))))
B17: =IF('Start Here'!C19="","",'Start Here'!C19) | K17: =IF($B17="","",COUNTA(C17:I17)-COUNTIF(C17:I17,"✗")) | L17: =IF('Start Here'!E19="","",'Start Here'!E19) | M17: =IF(OR($B17="",$L17=""),"",IF($K17>=$L17,"✓","")) | N17: =IF($B17="","",IF($C$7>TODAY(),"",IF(AND($C$7<=TODAY(),$I$7>=TODAY()),Engine!$AA$10,IFERROR(LOOKUP(2,1/(Engine!$A$3:$A$366<=$I$7),Engine!$W$3:$W$366),0))))
B18: =IF('Start Here'!C20="","",'Start Here'!C20) | K18: =IF($B18="","",COUNTA(C18:I18)-COUNTIF(C18:I18,"✗")) | L18: =IF('Start Here'!E20="","",'Start Here'!E20) | M18: =IF(OR($B18="",$L18=""),"",IF($K18>=$L18,"✓","")) | N18: =IF($B18="","",IF($C$7>TODAY(),"",IF(AND($C$7<=TODAY(),$I$7>=TODAY()),Engine!$AA$11,IFERROR(LOOKUP(2,1/(Engine!$A$3:$A$366<=$I$7),Engine!$X$3:$X$366),0))))
B20: DAILY TOTAL | C20: =IF(C$7>TODAY(),"",COUNTA(C9:C18)-COUNTIF(C9:C18,"✗")) | D20: =IF(D$7>TODAY(),"",COUNTA(D9:D18)-COUNTIF(D9:D18,"✗")) | E20: =IF(E$7>TODAY(),"",COUNTA(E9:E18)-COUNTIF(E9:E18,"✗")) | F20: =IF(F$7>TODAY(),"",COUNTA(F9:F18)-COUNTIF(F9:F18,"✗")) | G20: =IF(G$7>TODAY(),"",COUNTA(G9:G18)-COUNTIF(G9:G18,"✗")) | H20: =IF(H$7>TODAY(),"",COUNTA(H9:H18)-COUNTIF(H9:H18,"✗")) | I20: =IF(I$7>TODAY(),"",COUNTA(I9:I18)-COUNTIF(I9:I18,"✗")) | K20: =SUM(K9:K18) | L20: =SUM(L9:L18)
B22: WEEK SCORE | C22: =IF($C$7>TODAY(),"",IF(SUM($L$9:$L$18)=0,"",MIN(1,SUM($K$9:$K$18)/SUM($L$9:$L$18)))) | F22: PERFECT DAYS | H22: =IF(OR($C$7>TODAY(),SUMPRODUCT(--($B$9:$B$18<>""))=0),"",SUMPRODUCT(--($C$20:$I$20=SUMPRODUCT(--($B$9:$B$18<>""))))) | K22: TOP STREAK | M22: =IF(COUNT($N$9:$N$18)=0,"",MAX($N$9:$N$18))
B24: FOCUS THIS WEEK
B26: NOTES

Sheet W06
B2: MOMENTUM · WEEKLY HABIT SYSTEM
B3: WEEK 06 | K3: =TEXT(C7,"d mmm")&" – "&TEXT(I7,"d mmm yyyy")
B4: ◀ WEEK 05 | K4: ◆ DASHBOARD | M4: WEEK 07 ▶
B6: HABIT | C6: MON | D6: TUE | E6: WED | F6: THU | G6: FRI | H6: SAT | I6: SUN | K6: DONE | L6: GOAL | M6: HIT | N6: STREAK
C7: ='Start Here'!$E$6+35 | D7: ='Start Here'!$E$6+36 | E7: ='Start Here'!$E$6+37 | F7: ='Start Here'!$E$6+38 | G7: ='Start Here'!$E$6+39 | H7: ='Start Here'!$E$6+40 | I7: ='Start Here'!$E$6+41
B9: =IF('Start Here'!C11="","",'Start Here'!C11) | K9: =IF($B9="","",COUNTA(C9:I9)-COUNTIF(C9:I9,"✗")) | L9: =IF('Start Here'!E11="","",'Start Here'!E11) | M9: =IF(OR($B9="",$L9=""),"",IF($K9>=$L9,"✓","")) | N9: =IF($B9="","",IF($C$7>TODAY(),"",IF(AND($C$7<=TODAY(),$I$7>=TODAY()),Engine!$AA$2,IFERROR(LOOKUP(2,1/(Engine!$A$3:$A$366<=$I$7),Engine!$O$3:$O$366),0))))
B10: =IF('Start Here'!C12="","",'Start Here'!C12) | K10: =IF($B10="","",COUNTA(C10:I10)-COUNTIF(C10:I10,"✗")) | L10: =IF('Start Here'!E12="","",'Start Here'!E12) | M10: =IF(OR($B10="",$L10=""),"",IF($K10>=$L10,"✓","")) | N10: =IF($B10="","",IF($C$7>TODAY(),"",IF(AND($C$7<=TODAY(),$I$7>=TODAY()),Engine!$AA$3,IFERROR(LOOKUP(2,1/(Engine!$A$3:$A$366<=$I$7),Engine!$P$3:$P$366),0))))
B11: =IF('Start Here'!C13="","",'Start Here'!C13) | K11: =IF($B11="","",COUNTA(C11:I11)-COUNTIF(C11:I11,"✗")) | L11: =IF('Start Here'!E13="","",'Start Here'!E13) | M11: =IF(OR($B11="",$L11=""),"",IF($K11>=$L11,"✓","")) | N11: =IF($B11="","",IF($C$7>TODAY(),"",IF(AND($C$7<=TODAY(),$I$7>=TODAY()),Engine!$AA$4,IFERROR(LOOKUP(2,1/(Engine!$A$3:$A$366<=$I$7),Engine!$Q$3:$Q$366),0))))
B12: =IF('Start Here'!C14="","",'Start Here'!C14) | K12: =IF($B12="","",COUNTA(C12:I12)-COUNTIF(C12:I12,"✗")) | L12: =IF('Start Here'!E14="","",'Start Here'!E14) | M12: =IF(OR($B12="",$L12=""),"",IF($K12>=$L12,"✓","")) | N12: =IF($B12="","",IF($C$7>TODAY(),"",IF(AND($C$7<=TODAY(),$I$7>=TODAY()),Engine!$AA$5,IFERROR(LOOKUP(2,1/(Engine!$A$3:$A$366<=$I$7),Engine!$R$3:$R$366),0))))
B13: =IF('Start Here'!C15="","",'Start Here'!C15) | K13: =IF($B13="","",COUNTA(C13:I13)-COUNTIF(C13:I13,"✗")) | L13: =IF('Start Here'!E15="","",'Start Here'!E15) | M13: =IF(OR($B13="",$L13=""),"",IF($K13>=$L13,"✓","")) | N13: =IF($B13="","",IF($C$7>TODAY(),"",IF(AND($C$7<=TODAY(),$I$7>=TODAY()),Engine!$AA$6,IFERROR(LOOKUP(2,1/(Engine!$A$3:$A$366<=$I$7),Engine!$S$3:$S$366),0))))
B14: =IF('Start Here'!C16="","",'Start Here'!C16) | K14: =IF($B14="","",COUNTA(C14:I14)-COUNTIF(C14:I14,"✗")) | L14: =IF('Start Here'!E16="","",'Start Here'!E16) | M14: =IF(OR($B14="",$L14=""),"",IF($K14>=$L14,"✓","")) | N14: =IF($B14="","",IF($C$7>TODAY(),"",IF(AND($C$7<=TODAY(),$I$7>=TODAY()),Engine!$AA$7,IFERROR(LOOKUP(2,1/(Engine!$A$3:$A$366<=$I$7),Engine!$T$3:$T$366),0))))
B15: =IF('Start Here'!C17="","",'Start Here'!C17) | K15: =IF($B15="","",COUNTA(C15:I15)-COUNTIF(C15:I15,"✗")) | L15: =IF('Start Here'!E17="","",'Start Here'!E17) | M15: =IF(OR($B15="",$L15=""),"",IF($K15>=$L15,"✓","")) | N15: =IF($B15="","",IF($C$7>TODAY(),"",IF(AND($C$7<=TODAY(),$I$7>=TODAY()),Engine!$AA$8,IFERROR(LOOKUP(2,1/(Engine!$A$3:$A$366<=$I$7),Engine!$U$3:$U$366),0))))
B16: =IF('Start Here'!C18="","",'Start Here'!C18) | K16: =IF($B16="","",COUNTA(C16:I16)-COUNTIF(C16:I16,"✗")) | L16: =IF('Start Here'!E18="","",'Start Here'!E18) | M16: =IF(OR($B16="",$L16=""),"",IF($K16>=$L16,"✓","")) | N16: =IF($B16="","",IF($C$7>TODAY(),"",IF(AND($C$7<=TODAY(),$I$7>=TODAY()),Engine!$AA$9,IFERROR(LOOKUP(2,1/(Engine!$A$3:$A$366<=$I$7),Engine!$V$3:$V$366),0))))
B17: =IF('Start Here'!C19="","",'Start Here'!C19) | K17: =IF($B17="","",COUNTA(C17:I17)-COUNTIF(C17:I17,"✗")) | L17: =IF('Start Here'!E19="","",'Start Here'!E19) | M17: =IF(OR($B17="",$L17=""),"",IF($K17>=$L17,"✓","")) | N17: =IF($B17="","",IF($C$7>TODAY(),"",IF(AND($C$7<=TODAY(),$I$7>=TODAY()),Engine!$AA$10,IFERROR(LOOKUP(2,1/(Engine!$A$3:$A$366<=$I$7),Engine!$W$3:$W$366),0))))
B18: =IF('Start Here'!C20="","",'Start Here'!C20) | K18: =IF($B18="","",COUNTA(C18:I18)-COUNTIF(C18:I18,"✗")) | L18: =IF('Start Here'!E20="","",'Start Here'!E20) | M18: =IF(OR($B18="",$L18=""),"",IF($K18>=$L18,"✓","")) | N18: =IF($B18="","",IF($C$7>TODAY(),"",IF(AND($C$7<=TODAY(),$I$7>=TODAY()),Engine!$AA$11,IFERROR(LOOKUP(2,1/(Engine!$A$3:$A$366<=$I$7),Engine!$X$3:$X$366),0))))
B20: DAILY TOTAL | C20: =IF(C$7>TODAY(),"",COUNTA(C9:C18)-COUNTIF(C9:C18,"✗")) | D20: =IF(D$7>TODAY(),"",COUNTA(D9:D18)-COUNTIF(D9:D18,"✗")) | E20: =IF(E$7>TODAY(),"",COUNTA(E9:E18)-COUNTIF(E9:E18,"✗")) | F20: =IF(F$7>TODAY(),"",COUNTA(F9:F18)-COUNTIF(F9:F18,"✗")) | G20: =IF(G$7>TODAY(),"",COUNTA(G9:G18)-COUNTIF(G9:G18,"✗")) | H20: =IF(H$7>TODAY(),"",COUNTA(H9:H18)-COUNTIF(H9:H18,"✗")) | I20: =IF(I$7>TODAY(),"",COUNTA(I9:I18)-COUNTIF(I9:I18,"✗")) | K20: =SUM(K9:K18) | L20: =SUM(L9:L18)
B22: WEEK SCORE | C22: =IF($C$7>TODAY(),"",IF(SUM($L$9:$L$18)=0,"",MIN(1,SUM($K$9:$K$18)/SUM($L$9:$L$18)))) | F22: PERFECT DAYS | H22: =IF(OR($C$7>TODAY(),SUMPRODUCT(--($B$9:$B$18<>""))=0),"",SUMPRODUCT(--($C$20:$I$20=SUMPRODUCT(--($B$9:$B$18<>""))))) | K22: TOP STREAK | M22: =IF(COUNT($N$9:$N$18)=0,"",MAX($N$9:$N$18))
B24: FOCUS THIS WEEK
B26: NOTES

Sheet W07
B2: MOMENTUM · WEEKLY HABIT SYSTEM
B3: WEEK 07 | K3: =TEXT(C7,"d mmm")&" – "&TEXT(I7,"d mmm yyyy")
B4: ◀ WEEK 06 | K4: ◆ DASHBOARD | M4: WEEK 08 ▶
B6: HABIT | C6: MON | D6: TUE | E6: WED | F6: THU | G6: FRI | H6: SAT | I6: SUN | K6: DONE | L6: GOAL | M6: HIT | N6: STREAK
C7: ='Start Here'!$E$6+42 | D7: ='Start Here'!$E$6+43 | E7: ='Start Here'!$E$6+44 | F7: ='Start Here'!$E$6+45 | G7: ='Start Here'!$E$6+46 | H7: ='Start Here'!$E$6+47 | I7: ='Start Here'!$E$6+48
B9: =IF('Start Here'!C11="","",'Start Here'!C11) | K9: =IF($B9="","",COUNTA(C9:I9)-COUNTIF(C9:I9,"✗")) | L9: =IF('Start Here'!E11="","",'Start Here'!E11) | M9: =IF(OR($B9="",$L9=""),"",IF($K9>=$L9,"✓","")) | N9: =IF($B9="","",IF($C$7>TODAY(),"",IF(AND($C$7<=TODAY(),$I$7>=TODAY()),Engine!$AA$2,IFERROR(LOOKUP(2,1/(Engine!$A$3:$A$366<=$I$7),Engine!$O$3:$O$366),0))))
B10: =IF('Start Here'!C12="","",'Start Here'!C12) | K10: =IF($B10="","",COUNTA(C10:I10)-COUNTIF(C10:I10,"✗")) | L10: =IF('Start Here'!E12="","",'Start Here'!E12) | M10: =IF(OR($B10="",$L10=""),"",IF($K10>=$L10,"✓","")) | N10: =IF($B10="","",IF($C$7>TODAY(),"",IF(AND($C$7<=TODAY(),$I$7>=TODAY()),Engine!$AA$3,IFERROR(LOOKUP(2,1/(Engine!$A$3:$A$366<=$I$7),Engine!$P$3:$P$366),0))))
B11: =IF('Start Here'!C13="","",'Start Here'!C13) | K11: =IF($B11="","",COUNTA(C11:I11)-COUNTIF(C11:I11,"✗")) | L11: =IF('Start Here'!E13="","",'Start Here'!E13) | M11: =IF(OR($B11="",$L11=""),"",IF($K11>=$L11,"✓","")) | N11: =IF($B11="","",IF($C$7>TODAY(),"",IF(AND($C$7<=TODAY(),$I$7>=TODAY()),Engine!$AA$4,IFERROR(LOOKUP(2,1/(Engine!$A$3:$A$366<=$I$7),Engine!$Q$3:$Q$366),0))))
B12: =IF('Start Here'!C14="","",'Start Here'!C14) | K12: =IF($B12="","",COUNTA(C12:I12)-COUNTIF(C12:I12,"✗")) | L12: =IF('Start Here'!E14="","",'Start Here'!E14) | M12: =IF(OR($B12="",$L12=""),"",IF($K12>=$L12,"✓","")) | N12: =IF($B12="","",IF($C$7>TODAY(),"",IF(AND($C$7<=TODAY(),$I$7>=TODAY()),Engine!$AA$5,IFERROR(LOOKUP(2,1/(Engine!$A$3:$A$366<=$I$7),Engine!$R$3:$R$366),0))))
B13: =IF('Start Here'!C15="","",'Start Here'!C15) | K13: =IF($B13="","",COUNTA(C13:I13)-COUNTIF(C13:I13,"✗")) | L13: =IF('Start Here'!E15="","",'Start Here'!E15) | M13: =IF(OR($B13="",$L13=""),"",IF($K13>=$L13,"✓","")) | N13: =IF($B13="","",IF($C$7>TODAY(),"",IF(AND($C$7<=TODAY(),$I$7>=TODAY()),Engine!$AA$6,IFERROR(LOOKUP(2,1/(Engine!$A$3:$A$366<=$I$7),Engine!$S$3:$S$366),0))))
B14: =IF('Start Here'!C16="","",'Start Here'!C16) | K14: =IF($B14="","",COUNTA(C14:I14)-COUNTIF(C14:I14,"✗")) | L14: =IF('Start Here'!E16="","",'Start Here'!E16) | M14: =IF(OR($B14="",$L14=""),"",IF($K14>=$L14,"✓","")) | N14: =IF($B14="","",IF($C$7>TODAY(),"",IF(AND($C$7<=TODAY(),$I$7>=TODAY()),Engine!$AA$7,IFERROR(LOOKUP(2,1/(Engine!$A$3:$A$366<=$I$7),Engine!$T$3:$T$366),0))))
B15: =IF('Start Here'!C17="","",'Start Here'!C17) | K15: =IF($B15="","",COUNTA(C15:I15)-COUNTIF(C15:I15,"✗")) | L15: =IF('Start Here'!E17="","",'Start Here'!E17) | M15: =IF(OR($B15="",$L15=""),"",IF($K15>=$L15,"✓","")) | N15: =IF($B15="","",IF($C$7>TODAY(),"",IF(AND($C$7<=TODAY(),$I$7>=TODAY()),Engine!$AA$8,IFERROR(LOOKUP(2,1/(Engine!$A$3:$A$366<=$I$7),Engine!$U$3:$U$366),0))))
B16: =IF('Start Here'!C18="","",'Start Here'!C18) | K16: =IF($B16="","",COUNTA(C16:I16)-COUNTIF(C16:I16,"✗")) | L16: =IF('Start Here'!E18="","",'Start Here'!E18) | M16: =IF(OR($B16="",$L16=""),"",IF($K16>=$L16,"✓","")) | N16: =IF($B16="","",IF($C$7>TODAY(),"",IF(AND($C$7<=TODAY(),$I$7>=TODAY()),Engine!$AA$9,IFERROR(LOOKUP(2,1/(Engine!$A$3:$A$366<=$I$7),Engine!$V$3:$V$366),0))))
B17: =IF('Start Here'!C19="","",'Start Here'!C19) | K17: =IF($B17="","",COUNTA(C17:I17)-COUNTIF(C17:I17,"✗")) | L17: =IF('Start Here'!E19="","",'Start Here'!E19) | M17: =IF(OR($B17="",$L17=""),"",IF($K17>=$L17,"✓","")) | N17: =IF($B17="","",IF($C$7>TODAY(),"",IF(AND($C$7<=TODAY(),$I$7>=TODAY()),Engine!$AA$10,IFERROR(LOOKUP(2,1/(Engine!$A$3:$A$366<=$I$7),Engine!$W$3:$W$366),0))))
B18: =IF('Start Here'!C20="","",'Start Here'!C20) | K18: =IF($B18="","",COUNTA(C18:I18)-COUNTIF(C18:I18,"✗")) | L18: =IF('Start Here'!E20="","",'Start Here'!E20) | M18: =IF(OR($B18="",$L18=""),"",IF($K18>=$L18,"✓","")) | N18: =IF($B18="","",IF($C$7>TODAY(),"",IF(AND($C$7<=TODAY(),$I$7>=TODAY()),Engine!$AA$11,IFERROR(LOOKUP(2,1/(Engine!$A$3:$A$366<=$I$7),Engine!$X$3:$X$366),0))))
B20: DAILY TOTAL | C20: =IF(C$7>TODAY(),"",COUNTA(C9:C18)-COUNTIF(C9:C18,"✗")) | D20: =IF(D$7>TODAY(),"",COUNTA(D9:D18)-COUNTIF(D9:D18,"✗")) | E20: =IF(E$7>TODAY(),"",COUNTA(E9:E18)-COUNTIF(E9:E18,"✗")) | F20: =IF(F$7>TODAY(),"",COUNTA(F9:F18)-COUNTIF(F9:F18,"✗")) | G20: =IF(G$7>TODAY(),"",COUNTA(G9:G18)-COUNTIF(G9:G18,"✗")) | H20: =IF(H$7>TODAY(),"",COUNTA(H9:H18)-COUNTIF(H9:H18,"✗")) | I20: =IF(I$7>TODAY(),"",COUNTA(I9:I18)-COUNTIF(I9:I18,"✗")) | K20: =SUM(K9:K18) | L20: =SUM(L9:L18)
B22: WEEK SCORE | C22: =IF($C$7>TODAY(),"",IF(SUM($L$9:$L$18)=0,"",MIN(1,SUM($K$9:$K$18)/SUM($L$9:$L$18)))) | F22: PERFECT DAYS | H22: =IF(OR($C$7>TODAY(),SUMPRODUCT(--($B$9:$B$18<>""))=0),"",SUMPRODUCT(--($C$20:$I$20=SUMPRODUCT(--($B$9:$B$18<>""))))) | K22: TOP STREAK | M22: =IF(COUNT($N$9:$N$18)=0,"",MAX($N$9:$N$18))
B24: FOCUS THIS WEEK
B26: NOTES

Sheet W08
B2: MOMENTUM · WEEKLY HABIT SYSTEM
B3: WEEK 08 | K3: =TEXT(C7,"d mmm")&" – "&TEXT(I7,"d mmm yyyy")
B4: ◀ WEEK 07 | K4: ◆ DASHBOARD | M4: WEEK 09 ▶
B6: HABIT | C6: MON | D6: TUE | E6: WED | F6: THU | G6: FRI | H6: SAT | I6: SUN | K6: DONE | L6: GOAL | M6: HIT | N6: STREAK
C7: ='Start Here'!$E$6+49 | D7: ='Start Here'!$E$6+50 | E7: ='Start Here'!$E$6+51 | F7: ='Start Here'!$E$6+52 | G7: ='Start Here'!$E$6+53 | H7: ='Start Here'!$E$6+54 | I7: ='Start Here'!$E$6+55
B9: =IF('Start Here'!C11="","",'Start Here'!C11) | K9: =IF($B9="","",COUNTA(C9:I9)-COUNTIF(C9:I9,"✗")) | L9: =IF('Start Here'!E11="","",'Start Here'!E11) | M9: =IF(OR($B9="",$L9=""),"",IF($K9>=$L9,"✓","")) | N9: =IF($B9="","",IF($C$7>TODAY(),"",IF(AND($C$7<=TODAY(),$I$7>=TODAY()),Engine!$AA$2,IFERROR(LOOKUP(2,1/(Engine!$A$3:$A$366<=$I$7),Engine!$O$3:$O$366),0))))
B10: =IF('Start Here'!C12="","",'Start Here'!C12) | K10: =IF($B10="","",COUNTA(C10:I10)-COUNTIF(C10:I10,"✗")) | L10: =IF('Start Here'!E12="","",'Start Here'!E12) | M10: =IF(OR($B10="",$L10=""),"",IF($K10>=$L10,"✓","")) | N10: =IF($B10="","",IF($C$7>TODAY(),"",IF(AND($C$7<=TODAY(),$I$7>=TODAY()),Engine!$AA$3,IFERROR(LOOKUP(2,1/(Engine!$A$3:$A$366<=$I$7),Engine!$P$3:$P$366),0))))
B11: =IF('Start Here'!C13="","",'Start Here'!C13) | K11: =IF($B11="","",COUNTA(C11:I11)-COUNTIF(C11:I11,"✗")) | L11: =IF('Start Here'!E13="","",'Start Here'!E13) | M11: =IF(OR($B11="",$L11=""),"",IF($K11>=$L11,"✓","")) | N11: =IF($B11="","",IF($C$7>TODAY(),"",IF(AND($C$7<=TODAY(),$I$7>=TODAY()),Engine!$AA$4,IFERROR(LOOKUP(2,1/(Engine!$A$3:$A$366<=$I$7),Engine!$Q$3:$Q$366),0))))
B12: =IF('Start Here'!C14="","",'Start Here'!C14) | K12: =IF($B12="","",COUNTA(C12:I12)-COUNTIF(C12:I12,"✗")) | L12: =IF('Start Here'!E14="","",'Start Here'!E14) | M12: =IF(OR($B12="",$L12=""),"",IF($K12>=$L12,"✓","")) | N12: =IF($B12="","",IF($C$7>TODAY(),"",IF(AND($C$7<=TODAY(),$I$7>=TODAY()),Engine!$AA$5,IFERROR(LOOKUP(2,1/(Engine!$A$3:$A$366<=$I$7),Engine!$R$3:$R$366),0))))
B13: =IF('Start Here'!C15="","",'Start Here'!C15) | K13: =IF($B13="","",COUNTA(C13:I13)-COUNTIF(C13:I13,"✗")) | L13: =IF('Start Here'!E15="","",'Start Here'!E15) | M13: =IF(OR($B13="",$L13=""),"",IF($K13>=$L13,"✓","")) | N13: =IF($B13="","",IF($C$7>TODAY(),"",IF(AND($C$7<=TODAY(),$I$7>=TODAY()),Engine!$AA$6,IFERROR(LOOKUP(2,1/(Engine!$A$3:$A$366<=$I$7),Engine!$S$3:$S$366),0))))
B14: =IF('Start Here'!C16="","",'Start Here'!C16) | K14: =IF($B14="","",COUNTA(C14:I14)-COUNTIF(C14:I14,"✗")) | L14: =IF('Start Here'!E16="","",'Start Here'!E16) | M14: =IF(OR($B14="",$L14=""),"",IF($K14>=$L14,"✓","")) | N14: =IF($B14="","",IF($C$7>TODAY(),"",IF(AND($C$7<=TODAY(),$I$7>=TODAY()),Engine!$AA$7,IFERROR(LOOKUP(2,1/(Engine!$A$3:$A$366<=$I$7),Engine!$T$3:$T$366),0))))
B15: =IF('Start Here'!C17="","",'Start Here'!C17) | K15: =IF($B15="","",COUNTA(C15:I15)-COUNTIF(C15:I15,"✗")) | L15: =IF('Start Here'!E17="","",'Start Here'!E17) | M15: =IF(OR($B15="",$L15=""),"",IF($K15>=$L15,"✓","")) | N15: =IF($B15="","",IF($C$7>TODAY(),"",IF(AND($C$7<=TODAY(),$I$7>=TODAY()),Engine!$AA$8,IFERROR(LOOKUP(2,1/(Engine!$A$3:$A$366<=$I$7),Engine!$U$3:$U$366),0))))
